Workbook

Sheet All Simpanan 
A1: NO. | B1: NO. ANGGOTA | C1: NAMA ANGGOTA | D1: UNIT KERJA | E1: JUMLAH SIMPANAN ANGGOTA PERIODE JUNI 2025 | K1: STATUS
E2: WAJIB | F2: POKOK | G2: KHUSUS | H2: SUKARELA | I2: SUKARELA BERJANGKA | J2: JUMLAH
A3: 1 | B3: 000001 | C3: Aan Agus F, Amd. | D3: SBC | E3: =SUMIF('Simpanan Wajib'!C:C,'All Simpanan '!C:C,'Simpanan Wajib'!E:E) -> 0 | F3: =SUMIF('Simpanan Pokok'!C:C,'All Simpanan '!C:C,'Simpanan Pokok'!E:E) -> 0 | G3: =SUMIF('Simpanan Khusus'!C:C,'All Simpanan '!C:C,'Simpanan Khusus'!E:E) -> 0 | H3: =SUMIF('Simpanan Sukarela'!C:C,'All Simpanan '!C:C,'Simpanan Sukarela'!E:E) -> 0 | I3: =SUMIF('Simpanan Sukarela Berjangka'!B:B,'All Simpanan '!C:C,'Simpanan Sukarela Berjangka'!K:K) -> 0 | J3: =SUM(E3:I3) -> 0 | K3: AKTIF
A4: 2 | B4: 000002 | C4: Abdul Ghofar, Ir | D4: DOC | E4: =SUMIF('Simpanan Wajib'!C:C,'All Simpanan '!C:C,'Simpanan Wajib'!E:E) -> 0 | F4: =SUMIF('Simpanan Pokok'!C:C,'All Simpanan '!C:C,'Simpanan Pokok'!E:E) -> 0 | G4: =SUMIF('Simpanan Khusus'!C:C,'All Simpanan '!C:C,'Simpanan Khusus'!E:E) -> 0 | H4: =SUMIF('Simpanan Sukarela'!C:C,'All Simpanan '!C:C,'Simpanan Sukarela'!E:E) -> 0 | I4: =SUMIF('Simpanan Sukarela Berjangka'!B:B,'All Simpanan '!C:C,'Simpanan Sukarela Berjangka'!K:K) -> 0 | J4: =SUM(E4:I4) -> 0 | K4: BUKAN ANGGOTA
A5: 3 | B5: 000003 | C5: Abdul Hadi | E5: =SUMIF('Simpanan Wajib'!C:C,'All Simpanan '!C:C,'Simpanan Wajib'!E:E) -> 150000 | F5: =SUMIF('Simpanan Pokok'!C:C,'All Simpanan '!C:C,'Simpanan Pokok'!E:E) -> 0 | G5: =SUMIF('Simpanan Khusus'!C:C,'All Simpanan '!C:C,'Simpanan Khusus'!E:E) -> 0 | H5: =SUMIF('Simpanan Sukarela'!C:C,'All Simpanan '!C:C,'Simpanan Sukarela'!E:E) -> 6155 | I5: =SUMIF('Simpanan Sukarela Berjangka'!B:B,'All Simpanan '!C:C,'Simpanan Sukarela Berjangka'!K:K) -> 0 | J5: =SUM(E5:I5) -> 156155 | K5: BUKAN ANGGOTA
A6: 4 | B6: 000006 | C6: Abu Kasim Usman | D6: SB | E6: =SUMIF('Simpanan Wajib'!C:C,'All Simpanan '!C:C,'Simpanan Wajib'!E:E) -> 0 | F6: =SUMIF('Simpanan Pokok'!C:C,'All Simpanan '!C:C,'Simpanan Pokok'!E:E) -> 0 | G6: =SUMIF('Simpanan Khusus'!C:C,'All Simpanan '!C:C,'Simpanan Khusus'!E:E) -> 0 | H6: =SUMIF('Simpanan Sukarela'!C:C,'All Simpanan '!C:C,'Simpanan Sukarela'!E:E) -> 1217315.7 | I6: =SUMIF('Simpanan Sukarela Berjangka'!B:B,'All Simpanan '!C:C,'Simpanan Sukarela Berjangka'!K:K) -> 0 | J6: =SUM(E6:I6) -> 1217315.7 | K6: AKTIF
A7: 5 | B7: 000009 | C7: Achmad | D7: PUMA | E7: =SUMIF('Simpanan Wajib'!C:C,'All Simpanan '!C:C,'Simpanan Wajib'!E:E) -> 24852898 | F7: =SUMIF('Simpanan Pokok'!C:C,'All Simpanan '!C:C,'Simpanan Pokok'!E:E) -> 5000 | G7: =SUMIF('Simpanan Khusus'!C:C,'All Simpanan '!C:C,'Simpanan Khusus'!E:E) -> 795000 | H7: =SUMIF('Simpanan Sukarela'!C:C,'All Simpanan '!C:C,'Simpanan Sukarela'!E:E) -> 2229525.3 | I7: =SUMIF('Simpanan Sukarela Berjangka'!B:B,'All Simpanan '!C:C,'Simpanan Sukarela Berjangka'!K:K) -> 0 | J7: =SUM(E7:I7) -> 27882423 | K7: AKTIF
A8: 6 | B8: 000013 | C8: Achmad Muslim, Ir | D8: HCTIO | E8: =SUMIF('Simpanan Wajib'!C:C,'All Simpanan '!C:C,'Simpanan Wajib'!E:E) -> 0 | F8: =SUMIF('Simpanan Pokok'!C:C,'All Simpanan '!C:C,'Simpanan Pokok'!E:E) -> 0 | G8: =SUMIF('Simpanan Khusus'!C:C,'All Simpanan '!C:C,'Simpanan Khusus'!E:E) -> 0 | H8: =SUMIF('Simpanan Sukarela'!C:C,'All Simpanan '!C:C,'Simpanan Sukarela'!E:E) -> 0 | I8: =SUMIF('Simpanan Sukarela Berjangka'!B:B,'All Simpanan '!C:C,'Simpanan Sukarela Berjangka'!K:K) -> 0 | J8: =SUM(E8:I8) -> 0 | K8: AKTIF
A9: 7 | B9: 000014 | C9: Achmad Suseno, Ir | D9: R&P | E9: =SUMIF('Simpanan Wajib'!C:C,'All Simpanan '!C:C,'Simpanan Wajib'!E:E) -> 0 | F9: =SUMIF('Simpanan Pokok'!C:C,'All Simpanan '!C:C,'Simpanan Pokok'!E:E) -> 0 | G9: =SUMIF('Simpanan Khusus'!C:C,'All Simpanan '!C:C,'Simpanan Khusus'!E:E) -> 0 | H9: =SUMIF('Simpanan Sukarela'!C:C,'All Simpanan '!C:C,'Simpanan Sukarela'!E:E) -> 0 | I9: =SUMIF('Simpanan Sukarela Berjangka'!B:B,'All Simpanan '!C:C,'Simpanan Sukarela Berjangka'!K:K) -> 0 | J9: =SUM(E9:I9) -> 0 | K9: PASIF
A10: 8 | B10: 000015 | C10: Achmad Tawakkal | D10: DOC | E10: =SUMIF('Simpanan Wajib'!C:C,'All Simpanan '!C:C,'Simpanan Wajib'!E:E) -> 0 | F10: =SUMIF('Simpanan Pokok'!C:C,'All Simpanan '!C:C,'Simpanan Pokok'!E:E) -> 0 | G10: =SUMIF('Simpanan Khusus'!C:C,'All Simpanan '!C:C,'Simpanan Khusus'!E:E) -> 0 | H10: =SUMIF('Simpanan Sukarela'!C:C,'All Simpanan '!C:C,'Simpanan Sukarela'!E:E) -> 0 | I10: =SUMIF('Simpanan Sukarela Berjangka'!B:B,'All Simpanan '!C:C,'Simpanan Sukarela Berjangka'!K:K) -> 0 | J10: =SUM(E10:I10) -> 0 | K10: AKTIF
A11: 9 | B11: 000018 | C11: Ade Prihadi | D11: CG | E11: =SUMIF('Simpanan Wajib'!C:C,'All Simpanan '!C:C,'Simpanan Wajib'!E:E) -> 0 | F11: =SUMIF('Simpanan Pokok'!C:C,'All Simpanan '!C:C,'Simpanan Pokok'!E:E) -> 0 | G11: =SUMIF('Simpanan Khusus'!C:C,'All Simpanan '!C:C,'Simpanan Khusus'!E:E) -> 0 | H11: =SUMIF('Simpanan Sukarela'!C:C,'All Simpanan '!C:C,'Simpanan Sukarela'!E:E) -> 655986 | I11: =SUMIF('Simpanan Sukarela Berjangka'!B:B,'All Simpanan '!C:C,'Simpanan Sukarela Berjangka'!K:K) -> 0 | J11: =SUM(E11:I11) -> 655986 | K11: PASIF
A12: 10 | B12: 000019 | C12: Ade Sugandi | D12: - | E12: =SUMIF('Simpanan Wajib'!C:C,'All Simpanan '!C:C,'Simpanan Wajib'!E:E) -> 250000 | F12: =SUMIF('Simpanan Pokok'!C:C,'All Simpanan '!C:C,'Simpanan Pokok'!E:E) -> 0 | G12: =SUMIF('Simpanan Khusus'!C:C,'All Simpanan '!C:C,'Simpanan Khusus'!E:E) -> 100000 | H12: =SUMIF('Simpanan Sukarela'!C:C,'All Simpanan '!C:C,'Simpanan Sukarela'!E:E) -> 214116.94 | I12: =SUMIF('Simpanan Sukarela Berjangka'!B:B,'All Simpanan '!C:C,'Simpanan Sukarela Berjangka'!K:K) -> 0 | J12: =SUM(E12:I12) -> 564116.94 | K12: PASIF
A13: 11 | B13: 000020 | C13: Adhitama Rama, ST. | D13: PHP | E13: =SUMIF('Simpanan Wajib'!C:C,'All Simpanan '!C:C,'Simpanan Wajib'!E:E) -> 0 | F13: =SUMIF('Simpanan Pokok'!C:C,'All Simpanan '!C:C,'Simpanan Pokok'!E:E) -> 0 | G13: =SUMIF('Simpanan Khusus'!C:C,'All Simpanan '!C:C,'Simpanan Khusus'!E:E) -> 0 | H13: =SUMIF('Simpanan Sukarela'!C:C,'All Simpanan '!C:C,'Simpanan Sukarela'!E:E) -> 0 | I13: =SUMIF('Simpanan Sukarela Berjangka'!B:B,'All Simpanan '!C:C,'Simpanan Sukarela Berjangka'!K:K) -> 0 | J13: =SUM(E13:I13) -> 0 | K13: PASIF
A14: 12 | B14: 000021 | C14: Adi Iman Patria, B.Sc. | D14: HC&L | E14: =SUMIF('Simpanan Wajib'!C:C,'All Simpanan '!C:C,'Simpanan Wajib'!E:E) -> 0 | F14: =SUMIF('Simpanan Pokok'!C:C,'All Simpanan '!C:C,'Simpanan Pokok'!E:E) -> 0 | G14: =SUMIF('Simpanan Khusus'!C:C,'All Simpanan '!C:C,'Simpanan Khusus'!E:E) -> 0 | H14: =SUMIF('Simpanan Sukarela'!C:C,'All Simpanan '!C:C,'Simpanan Sukarela'!E:E) -> 0 | I14: =SUMIF('Simpanan Sukarela Berjangka'!B:B,'All Simpanan '!C:C,'Simpanan Sukarela Berjangka'!K:K) -> 0 | J14: =SUM(E14:I14) -> 0 | K14: BUKAN ANGGOTA
A15: 13 | B15: 000025 | C15: Aditia Warman | D15: - | E15: =SUMIF('Simpanan Wajib'!C:C,'All Simpanan '!C:C,'Simpanan Wajib'!E:E) -> 0 | F15: =SUMIF('Simpanan Pokok'!C:C,'All Simpanan '!C:C,'Simpanan Pokok'!E:E) -> 0 | G15: =SUMIF('Simpanan Khusus'!C:C,'All Simpanan '!C:C,'Simpanan Khusus'!E:E) -> 0 | H15: =SUMIF('Simpanan Sukarela'!C:C,'All Simpanan '!C:C,'Simpanan Sukarela'!E:E) -> 2245019 | I15: =SUMIF('Simpanan Sukarela Berjangka'!B:B,'All Simpanan '!C:C,'Simpanan Sukarela Berjangka'!K:K) -> 0 | J15: =SUM(E15:I15) -> 2245019 | K15: PASIF
A16: 14 | B16: 000026 | C16: Aditya Trisandriya P, ST | D16: STA | E16: =SUMIF('Simpanan Wajib'!C:C,'All Simpanan '!C:C,'Simpanan Wajib'!E:E) -> 0 | F16: =SUMIF('Simpanan Pokok'!C:C,'All Simpanan '!C:C,'Simpanan Pokok'!E:E) -> 0 | G16: =SUMIF('Simpanan Khusus'!C:C,'All Simpanan '!C:C,'Simpanan Khusus'!E:E) -> 0 | H16: =SUMIF('Simpanan Sukarela'!C:C,'All Simpanan '!C:C,'Simpanan Sukarela'!E:E) -> 0 | I16: =SUMIF('Simpanan Sukarela Berjangka'!B:B,'All Simpanan '!C:C,'Simpanan Sukarela Berjangka'!K:K) -> 0 | J16: =SUM(E16:I16) -> 0 | K16: AKTIF
A17: 15 | B17: 000027 | C17: Afrizal | D17: - | E17: =SUMIF('Simpanan Wajib'!C:C,'All Simpanan '!C:C,'Simpanan Wajib'!E:E) -> 0 | F17: =SUMIF('Simpanan Pokok'!C:C,'All Simpanan '!C:C,'Simpanan Pokok'!E:E) -> 0 | G17: =SUMIF('Simpanan Khusus'!C:C,'All Simpanan '!C:C,'Simpanan Khusus'!E:E) -> 0 | H17: =SUMIF('Simpanan Sukarela'!C:C,'All Simpanan '!C:C,'Simpanan Sukarela'!E:E) -> 131136.88 | I17: =SUMIF('Simpanan Sukarela Berjangka'!B:B,'All Simpanan '!C:C,'Simpanan Sukarela Berjangka'!K:K) -> 0 | J17: =SUM(E17:I17) -> 131136.88 | K17: PASIF
... A405: 403 | B405: 000650 | C405: Andre Guntur Teguh WS, ST. | D405: PB | E405: =SUMIF('Simpanan Wajib'!C:C,'All Simpanan '!C:C,'Simpanan Wajib'!E:E) -> 0 | F405: =SUMIF('Simpanan Pokok'!C:C,'All Simpanan '!C:C,'Simpanan Pokok'!E:E) -> 0 | G405: =SUMIF('Simpanan Khusus'!C:C,'All Simpanan '!C:C,'Simpanan Khusus'!E:E) -> 0 | H405: =SUMIF('Simpanan Sukarela'!C:C,'All Simpanan '!C:C,'Simpanan Sukarela'!E:E) -> 0 | I405: =SUMIF('Simpanan Sukarela Berjangka'!B:B,'All Simpanan '!C:C,'Simpanan Sukarela Berjangka'!K:K) -> 0 | J405: =SUM(E405:I405) -> 0 | K405: PASIF
A406: 404 | B406: 000651 | C406: Angga Santoso | E406: =SUMIF('Simpanan Wajib'!C:C,'All Simpanan '!C:C,'Simpanan Wajib'!E:E) -> 250000 | F406: =SUMIF('Simpanan Pokok'!C:C,'All Simpanan '!C:C,'Simpanan Pokok'!E:E) -> 0 | G406: =SUMIF('Simpanan Khusus'!C:C,'All Simpanan '!C:C,'Simpanan Khusus'!E:E) -> 0 | H406: =SUMIF('Simpanan Sukarela'!C:C,'All Simpanan '!C:C,'Simpanan Sukarela'!E:E) -> 10258 | I406: =SUMIF('Simpanan Sukarela Berjangka'!B:B,'All Simpanan '!C:C,'Simpanan Sukarela Berjangka'!K:K) -> 0 | J406: =SUM(E406:I406) -> 260258 | K406: PASIF
A407: 405 | B407: 000652 | C407: Angga Yustiawan, ST. | D407: BM | E407: =SUMIF('Simpanan Wajib'!C:C,'All Simpanan '!C:C,'Simpanan Wajib'!E:E) -> 0 | F407: =SUMIF('Simpanan Pokok'!C:C,'All Simpanan '!C:C,'Simpanan Pokok'!E:E) -> 0 | G407: =SUMIF('Simpanan Khusus'!C:C,'All Simpanan '!C:C,'Simpanan Khusus'!E:E) -> 0 | H407: =SUMIF('Simpanan Sukarela'!C:C,'All Simpanan '!C:C,'Simpanan Sukarela'!E:E) -> 0 | I407: =SUMIF('Simpanan Sukarela Berjangka'!B:B,'All Simpanan '!C:C,'Simpanan Sukarela Berjangka'!K:K) -> 0 | J407: =SUM(E407:I407) -> 0 | K407: PASIF
A408: 406 | B408: 000653 | C408: Angjuang Adi Panju P. , ST. | D408: R&P | E408: =SUMIF('Simpanan Wajib'!C:C,'All Simpanan '!C:C,'Simpanan Wajib'!E:E) -> 0 | F408: =SUMIF('Simpanan Pokok'!C:C,'All Simpanan '!C:C,'Simpanan Pokok'!E:E) -> 0 | G408: =SUMIF('Simpanan Khusus'!C:C,'All Simpanan '!C:C,'Simpanan Khusus'!E:E) -> 0 | H408: =SUMIF('Simpanan Sukarela'!C:C,'All Simpanan '!C:C,'Simpanan Sukarela'!E:E) -> 0 | I408: =SUMIF('Simpanan Sukarela Berjangka'!B:B,'All Simpanan '!C:C,'Simpanan Sukarela Berjangka'!K:K) -> 0 | J408: =SUM(E408:I408) -> 0 | K408: BUKAN ANGGOTA
A409: 407 | B409: 000655 | C409: Bambang Tri Nugroho | D409: BJC | E409: =SUMIF('Simpanan Wajib'!C:C,'All Simpanan '!C:C,'Simpanan Wajib'!E:E) -> 11395000 | F409: =SUMIF('Simpanan Pokok'!C:C,'All Simpanan '!C:C,'Simpanan Pokok'!E:E) -> 5000 | G409: =SUMIF('Simpanan Khusus'!C:C,'All Simpanan '!C:C,'Simpanan Khusus'!E:E) -> 0 | H409: =SUMIF('Simpanan Sukarela'!C:C,'All Simpanan '!C:C,'Simpanan Sukarela'!E:E) -> 2421596 | I409: =SUMIF('Simpanan Sukarela Berjangka'!B:B,'All Simpanan '!C:C,'Simpanan Sukarela Berjangka'!K:K) -> 0 | J409: =SUM(E409:I409) -> 13821596 | K409: AKTIF
A410: 408 | B410: 000656 | C410: Bayu Mahardika W, ST. | D410: DOK | E410: =SUMIF('Simpanan Wajib'!C:C,'All Simpanan '!C:C,'Simpanan Wajib'!E:E) -> 0 | F410: =SUMIF('Simpanan Pokok'!C:C,'All Simpanan '!C:C,'Simpanan Pokok'!E:E) -> 0 | G410: =SUMIF('Simpanan Khusus'!C:C,'All Simpanan '!C:C,'Simpanan Khusus'!E:E) -> 0 | H410: =SUMIF('Simpanan Sukarela'!C:C,'All Simpanan '!C:C,'Simpanan Sukarela'!E:E) -> 0 | I410: =SUMIF('Simpanan Sukarela Berjangka'!B:B,'All Simpanan '!C:C,'Simpanan Sukarela Berjangka'!K:K) -> 0 | J410: =SUM(E410:I410) -> 0 | K410: AKTIF
A411: 409 | B411: 000658 | C411: Bobby A. Novrianto | D411: ACD | E411: =SUMIF('Simpanan Wajib'!C:C,'All Simpanan '!C:C,'Simpanan Wajib'!E:E) -> 0 | F411: =SUMIF('Simpanan Pokok'!C:C,'All Simpanan '!C:C,'Simpanan Pokok'!E:E) -> 0 | G411: =SUMIF('Simpanan Khusus'!C:C,'All Simpanan '!C:C,'Simpanan Khusus'!E:E) -> 0 | H411: =SUMIF('Simpanan Sukarela'!C:C,'All Simpanan '!C:C,'Simpanan Sukarela'!E:E) -> 0 | I411: =SUMIF('Simpanan Sukarela Berjangka'!B:B,'All Simpanan '!C:C,'Simpanan Sukarela Berjangka'!K:K) -> 0 | J411: =SUM(E411:I411) -> 0 | K411: AKTIF
A412: 410 | B412: 000660 | C412: Budi Fitriawan, ST. | D412: PKK | E412: =SUMIF('Simpanan Wajib'!C:C,'All Simpanan '!C:C,'Simpanan Wajib'!E:E) -> 0 | F412: =SUMIF('Simpanan Pokok'!C:C,'All Simpanan '!C:C,'Simpanan Pokok'!E:E) -> 0 | G412: =SUMIF('Simpanan Khusus'!C:C,'All Simpanan '!C:C,'Simpanan Khusus'!E:E) -> 0 | H412: =SUMIF('Simpanan Sukarela'!C:C,'All Simpanan '!C:C,'Simpanan Sukarela'!E:E) -> 0 | I412: =SUMIF('Simpanan Sukarela Berjangka'!B:B,'All Simpanan '!C:C,'Simpanan Sukarela Berjangka'!K:K) -> 0 | J412: =SUM(E412:I412) -> 0 | K412: AKTIF
A413: 411 | B413: 000661 | C413: Budiwansyah | D413: PBC | E413: =SUMIF('Simpanan Wajib'!C:C,'All Simpanan '!C:C,'Simpanan Wajib'!E:E) -> 250000 | F413: =SUMIF('Simpanan Pokok'!C:C,'All Simpanan '!C:C,'Simpanan Pokok'!E:E) -> 0 | G413: =SUMIF('Simpanan Khusus'!C:C,'All Simpanan '!C:C,'Simpanan Khusus'!E:E) -> 0 | H413: =SUMIF('Simpanan Sukarela'!C:C,'All Simpanan '!C:C,'Simpanan Sukarela'!E:E) -> 751324 | I413: =SUMIF('Simpanan Sukarela Berjangka'!B:B,'All Simpanan '!C:C,'Simpanan Sukarela Berjangka'!K:K) -> 0 | J413: =SUM(E413:I413) -> 1001324 | K413: PASIF
A414: 412 | B414: 000662 | C414: Busrol | D414: ISPB | E414: =SUMIF('Simpanan Wajib'!C:C,'All Simpanan '!C:C,'Simpanan Wajib'!E:E) -> 0 | F414: =SUMIF('Simpanan Pokok'!C:C,'All Simpanan '!C:C,'Simpanan Pokok'!E:E) -> 0 | G414: =SUMIF('Simpanan Khusus'!C:C,'All Simpanan '!C:C,'Simpanan Khusus'!E:E) -> 0 | H414: =SUMIF('Simpanan Sukarela'!C:C,'All Simpanan '!C:C,'Simpanan Sukarela'!E:E) -> 0 | I414: =SUMIF('Simpanan Sukarela Berjangka'!B:B,'All Simpanan '!C:C,'Simpanan Sukarela Berjangka'!K:K) -> 0 | J414: =SUM(E414:I414) -> 0 | K414: AKTIF
A415: 413 | B415: 000663 | C415: Donny Putra Santika | D415: CG | E415: =SUMIF('Simpanan Wajib'!C:C,'All Simpanan '!C:C,'Simpanan Wajib'!E:E) -> 1970000 | F415: =SUMIF('Simpanan Pokok'!C:C,'All Simpanan '!C:C,'Simpanan Pokok'!E:E) -> 5000 | G415: =SUMIF('Simpanan Khusus'!C:C,'All Simpanan '!C:C,'Simpanan Khusus'!E:E) -> 0 | H415: =SUMIF('Simpanan Sukarela'!C:C,'All Simpanan '!C:C,'Simpanan Sukarela'!E:E) -> 1237384.1 | I415: =SUMIF('Simpanan Sukarela Berjangka'!B:B,'All Simpanan '!C:C,'Simpanan Sukarela Berjangka'!K:K) -> 0 | J415: =SUM(E415:I415) -> 3212384.1 | K415: PASIF
A416: 414 | B416: 000664 | C416: Eko Maja Priyanto, ST. | D416: SBU MNO | E416: =SUMIF('Simpanan Wajib'!C:C,'All Simpanan '!C:C,'Simpanan Wajib'!E:E) -> 0 | F416: =SUMIF('Simpanan Pokok'!C:C,'All Simpanan '!C:C,'Simpanan Pokok'!E:E) -> 0 | G416: =SUMIF('Simpanan Khusus'!C:C,'All Simpanan '!C:C,'Simpanan Khusus'!E:E) -> 0 | H416: =SUMIF('Simpanan Sukarela'!C:C,'All Simpanan '!C:C,'Simpanan Sukarela'!E:E) -> 0 | I416: =SUMIF('Simpanan Sukarela Berjangka'!B:B,'All Simpanan '!C:C,'Simpanan Sukarela Berjangka'!K:K) -> 0 | J416: =SUM(E416:I416) -> 0 | K416: PASIF
A417: 415 | B417: 000665 | C417: Fachruddin, ST. | D417: PRB | E417: =SUMIF('Simpanan Wajib'!C:C,'All Simpanan '!C:C,'Simpanan Wajib'!E:E) -> 0 | F417: =SUMIF('Simpanan Pokok'!C:C,'All Simpanan '!C:C,'Simpanan Pokok'!E:E) -> 0 | G417: =SUMIF('Simpanan Khusus'!C:C,'All Simpanan '!C:C,'Simpanan Khusus'!E:E) -> 0 | H417: =SUMIF('Simpanan Sukarela'!C:C,'All Simpanan '!C:C,'Simpanan Sukarela'!E:E) -> 0 | I417: =SUMIF('Simpanan Sukarela Berjangka'!B:B,'All Simpanan '!C:C,'Simpanan Sukarela Berjangka'!K:K) -> 0 | J417: =SUM(E417:I417) -> 0 | K417: AKTIF
A418: 416 | B418: 000666 | C418: Fachruddin Nur, ST. | D418: R&P | E418: =SUMIF('Simpanan Wajib'!C:C,'All Simpanan '!C:C,'Simpanan Wajib'!E:E) -> 0 | F418: =SUMIF('Simpanan Pokok'!C:C,'All Simpanan '!C:C,'Simpanan Pokok'!E:E) -> 0 | G418: =SUMIF('Simpanan Khusus'!C:C,'All Simpanan '!C:C,'Simpanan Khusus'!E:E) -> 0 | H418: =SUMIF('Simpanan Sukarela'!C:C,'All Simpanan '!C:C,'Simpanan Sukarela'!E:E) -> 0 | I418: =SUMIF('Simpanan Sukarela Berjangka'!B:B,'All Simpanan '!C:C,'Simpanan Sukarela Berjangka'!K:K) -> 0 | J418: =SUM(E418:I418) -> 0 | K418: PASIF
... A420: 418 | B420: 000669 | C420: Hendra, ST, | D420: BM | E420: =SUMIF('Simpanan Wajib'!C:C,'All Simpanan '!C:C,'Simpanan Wajib'!E:E) -> 0 | F420: =SUMIF('Simpanan Pokok'!C:C,'All Simpanan '!C:C,'Simpanan Pokok'!E:E) -> 0 | G420: =SUMIF('Simpanan Khusus'!C:C,'All Simpanan '!C:C,'Simpanan Khusus'!E:E) -> 0 | H420: =SUMIF('Simpanan Sukarela'!C:C,'All Simpanan '!C:C,'Simpanan Sukarela'!E:E) -> 0 | I420: =SUMIF('Simpanan Sukarela Berjangka'!B:B,'All Simpanan '!C:C,'Simpanan Sukarela Berjangka'!K:K) -> 0 | J420: =SUM(E420:I420) -> 0 | K420: PASIF
A421: 419 | B421: 000671 | C421: Hendra Saputra | E421: =SUMIF('Simpanan Wajib'!C:C,'All Simpanan '!C:C,'Simpanan Wajib'!E:E) -> 0 | F421: =SUMIF('Simpanan Pokok'!C:C,'All Simpanan '!C:C,'Simpanan Pokok'!E:E) -> 0 | G421: =SUMIF('Simpanan Khusus'!C:C,'All Simpanan '!C:C,'Simpanan Khusus'!E:E) -> 0 | H421: =SUMIF('Simpanan Sukarela'!C:C,'All Simpanan '!C:C,'Simpanan Sukarela'!E:E) -> 50040 | I421: =SUMIF('Simpanan Sukarela Berjangka'!B:B,'All Simpanan '!C:C,'Simpanan Sukarela Berjangka'!K:K) -> 0 | J421: =SUM(E421:I421) -> 50040 | K421: PASIF
A422: 420 | B422: 000672 | C422: I Gusti Ngurah Wira P, ST. | D422: PR | E422: =SUMIF('Simpanan Wajib'!C:C,'All Simpanan '!C:C,'Simpanan Wajib'!E:E) -> 0 | F422: =SUMIF('Simpanan Pokok'!C:C,'All Simpanan '!C:C,'Simpanan Pokok'!E:E) -> 0 | G422: =SUMIF('Simpanan Khusus'!C:C,'All Simpanan '!C:C,'Simpanan Khusus'!E:E) -> 0 | H422: =SUMIF('Simpanan Sukarela'!C:C,'All Simpanan '!C:C,'Simpanan Sukarela'!E:E) -> 0 | I422: =SUMIF('Simpanan Sukarela Berjangka'!B:B,'All Simpanan '!C:C,'Simpanan Sukarela Berjangka'!K:K) -> 0 | J422: =SUM(E422:I422) -> 0 | K422: PASIF
A423: 421 | B423: 000676 | C423: Indra Mariska Amd. | D423: PBC | E423: =SUMIF('Simpanan Wajib'!C:C,'All Simpanan '!C:C,'Simpanan Wajib'!E:E) -> 0 | F423: =SUMIF('Simpanan Pokok'!C:C,'All Simpanan '!C:C,'Simpanan Pokok'!E:E) -> 0 | G423: =SUMIF('Simpanan Khusus'!C:C,'All Simpanan '!C:C,'Simpanan Khusus'!E:E) -> 0 | H423: =SUMIF('Simpanan Sukarela'!C:C,'All Simpanan '!C:C,'Simpanan Sukarela'!E:E) -> 0 | I423: =SUMIF('Simpanan Sukarela Berjangka'!B:B,'All Simpanan '!C:C,'Simpanan Sukarela Berjangka'!K:K) -> 0 | J423: =SUM(E423:I423) -> 0 | K423: PASIF
A424: 422 | B424: 000679 | C424: Kartika Kushendra, Dr. | D424: MNO | E424: =SUMIF('Simpanan Wajib'!C:C,'All Simpanan '!C:C,'Simpanan Wajib'!E:E) -> 0 | F424: =SUMIF('Simpanan Pokok'!C:C,'All Simpanan '!C:C,'Simpanan Pokok'!E:E) -> 0 | G424: =SUMIF('Simpanan Khusus'!C:C,'All Simpanan '!C:C,'Simpanan Khusus'!E:E) -> 0 | H424: =SUMIF('Simpanan Sukarela'!C:C,'All Simpanan '!C:C,'Simpanan Sukarela'!E:E) -> 0 | I424: =SUMIF('Simpanan Sukarela Berjangka'!B:B,'All Simpanan '!C:C,'Simpanan Sukarela Berjangka'!K:K) -> 0 | J424: =SUM(E424:I424) -> 0 | K424: AKTIF
A425: 423 | B425: 000680 | C425: Khairul Akbar ST. | D425: PBC | E425: =SUMIF('Simpanan Wajib'!C:C,'All Simpanan '!C:C,'Simpanan Wajib'!E:E) -> 0 | F425: =SUMIF('Simpanan Pokok'!C:C,'All Simpanan '!C:C,'Simpanan Pokok'!E:E) -> 0 | G425: =SUMIF('Simpanan Khusus'!C:C,'All Simpanan '!C:C,'Simpanan Khusus'!E:E) -> 0 | H425: =SUMIF('Simpanan Sukarela'!C:C,'All Simpanan '!C:C,'Simpanan Sukarela'!E:E) -> 0 | I425: =SUMIF('Simpanan Sukarela Berjangka'!B:B,'All Simpanan '!C:C,'Simpanan Sukarela Berjangka'!K:K) -> 0 | J425: =SUM(E425:I425) -> 0 | K425: AKTIF
A426: 424 | B426: 000681 | C426: LA Ode Abdul Rahman F, ST. | D426: SD | E426: =SUMIF('Simpanan Wajib'!C:C,'All Simpanan '!C:C,'Simpanan Wajib'!E:E) -> 0 | F426: =SUMIF('Simpanan Pokok'!C:C,'All Simpanan '!C:C,'Simpanan Pokok'!E:E) -> 0 | G426: =SUMIF('Simpanan Khusus'!C:C,'All Simpanan '!C:C,'Simpanan Khusus'!E:E) -> 0 | H426: =SUMIF('Simpanan Sukarela'!C:C,'All Simpanan '!C:C,'Simpanan Sukarela'!E:E) -> 0 | I426: =SUMIF('Simpanan Sukarela Berjangka'!B:B,'All Simpanan '!C:C,'Simpanan Sukarela Berjangka'!K:K) -> 0 | J426: =SUM(E426:I426) -> 0 | K426: AKTIF
A427: 425 | B427: 000683 | C427: M. Yudi Oktavianto, ST. | D427: RP | E427: =SUMIF('Simpanan Wajib'!C:C,'All Simpanan '!C:C,'Simpanan Wajib'!E:E) -> 0 | F427: =SUMIF('Simpanan Pokok'!C:C,'All Simpanan '!C:C,'Simpanan Pokok'!E:E) -> 0 | G427: =SUMIF('Simpanan Khusus'!C:C,'All Simpanan '!C:C,'Simpanan Khusus'!E:E) -> 0 | H427: =SUMIF('Simpanan Sukarela'!C:C,'All Simpanan '!C:C,'Simpanan Sukarela'!E:E) -> 0 | I427: =SUMIF('Simpanan Sukarela Berjangka'!B:B,'All Simpanan '!C:C,'Simpanan Sukarela Berjangka'!K:K) -> 0 | J427: =SUM(E427:I427) -> 0 | K427: AKTIF
A428: 426 | B428: 000684 | C428: Mahesa Saga, ST. | D428: SB | E428: =SUMIF('Simpanan Wajib'!C:C,'All Simpanan '!C:C,'Simpanan Wajib'!E:E) -> 0 | F428: =SUMIF('Simpanan Pokok'!C:C,'All Simpanan '!C:C,'Simpanan Pokok'!E:E) -> 0 | G428: =SUMIF('Simpanan Khusus'!C:C,'All Simpanan '!C:C,'Simpanan Khusus'!E:E) -> 0 | H428: =SUMIF('Simpanan Sukarela'!C:C,'All Simpanan '!C:C,'Simpanan Sukarela'!E:E) -> 0 | I428: =SUMIF('Simpanan Sukarela Berjangka'!B:B,'All Simpanan '!C:C,'Simpanan Sukarela Berjangka'!K:K) -> 0 | J428: =SUM(E428:I428) -> 0 | K428: AKTIF
...

Sheet Simpanan Wajib
A1: NO. | C1: NAMA ANGGOTA | D1: UNIT KERJA | E1: SIMPANAN WAJIB 2024 | F1: Pembayaran Selama 2025 | R1: SALDO 2025
B2: NO. ANGGOTA | F2: Januari | G2: Februari | H2: Maret | I2: April | J2: Mei | K2: Juni | L2: Juli | M2: Agustus | N2: September | O2: Oktober | P2: November | Q2: Desember
A3: 1 | B3: 000001 | C3: A'AN AGUS FIRMANSYAH | D3: SBC | E3: 17240660 | F3: 150000 | G3: 150000 | H3: 150000 | I3: 150000 | J3: 150000 | K3: 150000 | L3: 150000 | M3: 150000 | N3: 150000 | O3: 150000 | P3: 150000 | Q3: 150000 | R3: =SUM(E3:Q3) -> 19040660
A4: 2 | B4: 000002 | C4: Abdul Ghofar | D4: DOC | E4: 0 | F4: 0 | G4: 0 | H4: 0 | I4: 0 | J4: 0 | K4: 0 | L4: 0 | M4: 0 | N4: 0 | O4: 0 | P4: 0 | R4: =SUM(E4:Q4) -> 0
A5: 3 | B5: 000003 | C5: Abdul Hadi | E5: 150000 | F5: 0 | G5: 0 | H5: 0 | I5: 0 | J5: 0 | K5: 0 | L5: 0 | M5: 0 | N5: 0 | O5: 0 | P5: 0 | R5: =SUM(E5:Q5) -> 150000
A6: 4 | B6: 000006 | C6: ABUKASIM USMAN | D6: SB | E6: 10609532 | F6: 150000 | G6: 150000 | H6: 150000 | I6: 150000 | J6: 150000 | K6: 150000 | L6: 150000 | M6: 150000 | N6: 150000 | O6: 150000 | P6: 150000 | Q6: 150000 | R6: =SUM(E6:Q6) -> 12409532
A7: 5 | B7: 000009 | C7: Achmad | D7: PUMA | E7: 24852898 | F7: 150000 | G7: 150000 | H7: 150000 | I7: 150000 | J7: 150000 | K7: 150000 | L7: 150000 | M7: 150000 | N7: 150000 | O7: 0 | P7: -26202898 | R7: =SUM(E7:Q7) -> 0
A8: 6 | B8: 000013 | C8: AKHMAD MUSLIM | D8: HCTIO | E8: 37699463 | F8: 500000 | G8: 500000 | H8: 500000 | I8: 500000 | J8: 500000 | K8: 500000 | L8: 500000 | M8: 500000 | N8: 0 | O8: -41699463 | P8: 0 | R8: =SUM(E8:Q8) -> 0
A9: 7 | B9: 000014 | C9: Achmad Suseno | D9: R&P | E9: 0 | F9: 0 | G9: 0 | H9: 0 | I9: 0 | J9: 0 | K9: 0 | L9: 0 | M9: 0 | N9: 0 | O9: 0 | P9: 0 | R9: =SUM(E9:Q9) -> 0
A10: 8 | B10: 000015 | C10: ACHMAD TAWAKKAL RAMPA | D10: DOC | E10: 34674262 | F10: 250000 | G10: 250000 | H10: 250000 | I10: 250000 | J10: 250000 | K10: 250000 | L10: 250000 | M10: 250000 | N10: 250000 | O10: 250000 | P10: 250000 | Q10: 250000 | R10: =SUM(E10:Q10) -> 37674262
A11: 9 | B11: 000018 | C11: Ade Prihadi | D11: CG | E11: 0 | F11: 0 | G11: 0 | H11: 0 | I11: 0 | J11: 0 | K11: 0 | L11: 0 | M11: 0 | N11: 0 | O11: 0 | P11: 0 | R11: =SUM(E11:Q11) -> 0
A12: 10 | B12: 000019 | C12: Ade Sugandi | D12: - | E12: 250000 | F12: 0 | G12: 0 | H12: 0 | I12: 0 | J12: 0 | K12: 0 | L12: 0 | M12: 0 | N12: 0 | O12: 0 | P12: 0 | R12: =SUM(E12:Q12) -> 250000
A13: 11 | B13: 000020 | C13: Adhitama Rama | D13: PHP | E13: 0 | F13: 0 | G13: 0 | H13: 0 | I13: 0 | J13: 0 | K13: 0 | L13: 0 | M13: 0 | N13: 0 | O13: 0 | P13: 0 | R13: =SUM(E13:Q13) -> 0
A14: 12 | B14: 000021 | C14: Adi Iman Patria | D14: HC&L | E14: 0 | F14: 0 | G14: 0 | H14: 0 | I14: 0 | J14: 0 | K14: 0 | L14: 0 | M14: 0 | N14: 0 | O14: 0 | P14: 0 | R14: =SUM(E14:Q14) -> 0
A15: 13 | B15: 000025 | C15: Aditia Warman | D15: - | E15: 0 | F15: 0 | G15: 0 | H15: 0 | I15: 0 | J15: 0 | K15: 0 | L15: 0 | M15: 0 | N15: 0 | O15: 0 | P15: 0 | R15: =SUM(E15:Q15) -> 0
A16: 14 | B16: 000026 | C16: ADITYA TRISANDHYA PRAMANA | D16: STA | E16: 44697275 | F16: 350000 | G16: 350000 | H16: 350000 | I16: 350000 | J16: 350000 | K16: 350000 | L16: 350000 | M16: 350000 | N16: 350000 | O16: 350000 | P16: 350000 | Q16: 350000 | R16: =SUM(E16:Q16) -> 48897275
A17: 15 | B17: 000027 | C17: Afrizal | D17: - | E17: 0 | F17: 0 | G17: 0 | H17: 0 | I17: 0 | J17: 0 | K17: 0 | L17: 0 | M17: 0 | N17: 0 | O17: 0 | P17: 0 | R17: =SUM(E17:Q17) -> 0
A18: 16 | B18: 000029 | C18: Agung Budi Arnanto | D18: PU | E18: 0 | F18: 0 | G18: 0 | H18: 0 | I18: 0 | J18: 0 | K18: 0 | L18: 0 | M18: 0 | N18: 0 | O18: 0 | P18: 0 | R18: =SUM(E18:Q18) -> 0
A19: 17 | B19: 000030 | C19: Agung Prihanto | D19: HCTIO | E19: 77549876 | F19: -77549876 | G19: 0 | H19: 0 | I19: 0 | J19: 0 | K19: 0 | L19: 0 | M19: 0 | N19: 0 | O19: 0 | P19: 0 | R19: =SUM(E19:Q19) -> 0
A20: 18 | B20: 000031 | C20: Agung Wicaksono | D20: SB | E20: 0 | F20: 0 | G20: 0 | H20: 0 | I20: 0 | J20: 0 | K20: 0 | L20: 0 | M20: 0 | N20: 0 | O20: 0 | P20: 0 | R20: =SUM(E20:Q20) -> 0
A21: 19 | B21: 000032 | C21: Agus Siswoko | D21: PRB | E21: 0 | F21: 0 | G21: 0 | H21: 0 | I21: 0 | J21: 0 | K21: 0 | L21: 0 | M21: 0 | N21: 0 | O21: 0 | P21: 0 | R21: =SUM(E21:Q21) -> 0
A22: 20 | B22: 000033 | C22: Agus Salim | D22: PRB | E22: 0 | F22: 0 | G22: 0 | H22: 0 | I22: 0 | J22: 0 | K22: 0 | L22: 0 | M22: 0 | N22: 0 | O22: 0 | P22: 0 | R22: =SUM(E22:Q22) -> 0
A23: 21 | B23: 000037 | C23: Agustang | D23: BM | E23: 250000 | F23: 0 | G23: 0 | H23: 0 | I23: 0 | J23: 0 | K23: 0 | L23: 0 | M23: 0 | N23: 0 | O23: 0 | P23: 0 | R23: =SUM(E23:Q23) -> 250000
A24: 22 | B24: 000039 | C24: Ahmad Aliyudin | D24: MHC | E24: -150000 | F24: 0 | G24: 0 | H24: 0 | I24: 0 | J24: 0 | K24: 0 | L24: 0 | M24: 0 | N24: 0 | O24: 0 | P24: 0 | R24: =SUM(E24:Q24) -> -150000
A25: 23 | B25: 000042 | C25: Ahmad Rifaid | D25: PR | E25: 0 | F25: 0 | G25: 0 | H25: 0 | I25: 0 | J25: 0 | K25: 0 | L25: 0 | M25: 0 | N25: 0 | O25: 0 | P25: 0 | R25: =SUM(E25:Q25) -> 0
A26: 24 | B26: 000043 | C26: Ahmad Sariful Anwar | D26: PRB | E26: 0 | F26: 0 | G26: 0 | H26: 0 | I26: 0 | J26: 0 | K26: 0 | L26: 0 | M26: 0 | N26: 0 | O26: 0 | P26: 0 | R26: =SUM(E26:Q26) -> 0
A27: 25 | B27: 000044 | C27: AHMAD YUNUS | D27: PU | E27: 13231788 | F27: 100000 | G27: 100000 | H27: 100000 | I27: 100000 | J27: 100000 | K27: 100000 | L27: 100000 | M27: 100000 | N27: 100000 | O27: 100000 | P27: 100000 | Q27: 100000 | R27: =SUM(E27:Q27) -> 14431788
A28: 26 | B28: 000045 | C28: AHMAD ZAKKY | D28: MHC | E28: 800000 | F28: 0 | G28: 0 | H28: 0 | I28: 0 | J28: 0 | K28: 0 | L28: 0 | M28: 0 | N28: 0 | O28: 0 | P28: 0 | R28: =SUM(E28:Q28) -> 800000
A29: 27 | B29: 000048 | C29: AKHMAD MULIADDIN | D29: PBC | E29: 18900000 | F29: 150000 | G29: 150000 | H29: 150000 | I29: 150000 | J29: 150000 | K29: 150000 | L29: 150000 | M29: 150000 | N29: 150000 | O29: 150000 | P29: 150000 | Q29: 150000 | R29: =SUM(E29:Q29) -> 20700000
A30: 28 | B30: 000052 | C30: Alfonsus Susilarso | D30: SV | E30: 0 | F30: 0 | G30: 0 | H30: 0 | I30: 0 | J30: 0 | K30: 0 | L30: 0 | M30: 0 | N30: 0 | O30: 0 | P30: 0 | R30: =SUM(E30:Q30) -> 0
A31: 29 | B31: 000053 | C31: ALI AKBAR BASO | D31: TP | E31: 4600000 | F31: 0 | G31: 0 | H31: 0 | I31: 0 | J31: 0 | K31: 0 | L31: 0 | M31: 350000 | N31: 350000 | O31: 350000 | P31: 350000 | Q31: 350000 | R31: =SUM(E31:Q31) -> 6350000
A32: 30 | B32: 000056 | C32: Alim Saadi | D32: R&P | E32: 67026138 | F32: 0 | G32: 0 | H32: 0 | I32: 0 | J32: 0 | K32: 0 | L32: 0 | M32: 0 | N32: 0 | O32: 0 | P32: 0 | R32: =SUM(E32:Q32) -> 67026138
A33: 31 | B33: 000059 | C33: ANDI ARDI ABDULLAH | D33: MKSC | E33: 12814161 | F33: 150000 | G33: 150000 | H33: 150000 | I33: 150000 | J33: 150000 | K33: 150000 | L33: 150000 | M33: 150000 | N33: 150000 | O33: 150000 | P33: 150000 | Q33: 150000 | R33: =SUM(E33:Q33) -> 14614161
A34: 32 | B34: 000060 | C34: Andi Arman | D34: SV | E34: 26027980 | F34: 0 | G34: 0 | H34: 0 | I34: 0 | J34: 0 | K34: 0 | L34: 0 | M34: 0 | N34: 0 | O34: 0 | P34: 0 | R34: =SUM(E34:Q34) -> 26027980
A35: 33 | B35: 000062 | C35: ANDI LAMAPPASESSU | D35: PSMMO | E35: 47029884 | F35: 350000 | G35: 350000 | H35: 350000 | I35: 350000 | J35: 350000 | K35: 350000 | L35: 350000 | M35: 350000 | N35: 350000 | O35: 350000 | P35: 350000 | Q35: 350000 | R35: =SUM(E35:Q35) -> 51229884
A36: 34 | B36: 000064 | C36: ANDI NURALIM KAMAL | D36: PRB | E36: 40939498 | F36: 350000 | G36: 350000 | H36: 350000 | I36: 350000 | J36: 350000 | K36: 350000 | L36: 350000 | M36: 350000 | N36: 350000 | O36: 350000 | P36: 350000 | Q36: 350000 | R36: =SUM(E36:Q36) -> 45139498
A37: 35 | B37: 000065 | C37: ANDI P. SIAGIAN | D37: BN | E37: 25567478 | F37: 250000 | G37: 250000 | H37: 250000 | I37: 250000 | J37: 250000 | K37: 250000 | L37: 250000 | M37: 250000 | N37: 250000 | O37: 250000 | P37: 250000 | Q37: 250000 | R37: =SUM(E37:Q37) -> 28567478
A38: 36 | B38: 000067 | C38: ANDRI SURYAWAN | D38: LC | E38: 39095000 | F38: 350000 | G38: 350000 | H38: 350000 | I38: 350000 | J38: 350000 | K38: 350000 | L38: 350000 | M38: 350000 | N38: 350000 | O38: 350000 | P38: 350000 | Q38: 350000 | R38: =SUM(E38:Q38) -> 43295000
A39: 37 | B39: 000070 | C39: Anita Magdalena | D39: SPI | E39: 36018134 | F39: 250000 | G39: 250000 | H39: 250000 | I39: 250000 | J39: 250000 | K39: 250000 | L39: 250000 | M39: 250000 | N39: 250000 | O39: 250000 | P39: 250000 | Q39: 250000 | R39: =SUM(E39:Q39) -> 39018134
A40: 38 | B40: 000071 | C40: ANOGI AKBAR ALI | D40: PSMMO | E40: 52878542 | F40: 350000 | G40: 350000 | H40: 350000 | I40: 350000 | J40: 350000 | K40: 350000 | L40: 350000 | M40: 350000 | N40: 350000 | O40: 350000 | P40: 350000 | Q40: 350000 | R40: =SUM(E40:Q40) -> 57078542
...

Sheet Simpanan Pokok
A1: NO. | B1: NO. ANGGOTA | C1: NAMA ANGGOTA | D1: UNIT KERJA | E1: Pokok 2024 | F1: Transaksi selama 2025 | R1: Saldo 2025
F2: Januari | G2: Februari | H2: Maret | I2: April | J2: Mei | K2: Juni | L2: Juli | M2: Agustus | N2: September | O2: Oktober | P2: November | Q2: Desember
A3: 1 | B3: 000001 | C3: A'AN AGUS FIRMANSYAH | D3: SBC | E3: 5000 | R3: =E3+F3+G3+H3+I3+J3+K3+L3+M3+N3+O3+P3+Q3 -> 5000
A4: =A3+1 -> 2 | B4: 000002 | C4: Abdul Ghofar | D4: DOC | E4: 0 | R4: =E4+F4+G4+H4+I4+J4+K4+L4+M4+N4+O4+P4+Q4 -> 0
A5: =A4+1 -> 3 | B5: 000003 | C5: Abdul Hadi | E5: 0 | R5: =E5+F5+G5+H5+I5+J5+K5+L5+M5+N5+O5+P5+Q5 -> 0
A6: =A5+1 -> 4 | B6: 000006 | C6: ABUKASIM USMAN | D6: SB | E6: 5000 | R6: =E6+F6+G6+H6+I6+J6+K6+L6+M6+N6+O6+P6+Q6 -> 5000
A7: =A6+1 -> 5 | B7: 000009 | C7: Achmad | D7: PUMA | E7: 5000 | P7: -5000 | R7: =E7+F7+G7+H7+I7+J7+K7+L7+M7+N7+O7+P7+Q7 -> 0
A8: =A7+1 -> 6 | B8: 000013 | C8: AKHMAD MUSLIM | D8: HCTIO | E8: 5000 | O8: -5000 | R8: =E8+F8+G8+H8+I8+J8+K8+L8+M8+N8+O8+P8+Q8 -> 0
A9: =A8+1 -> 7 | B9: 000014 | C9: Achmad Suseno | D9: R&P | E9: 0 | R9: =E9+F9+G9+H9+I9+J9+K9+L9+M9+N9+O9+P9+Q9 -> 0
A10: =A9+1 -> 8 | B10: 000015 | C10: ACHMAD TAWAKKAL RAMPA | D10: DOC | E10: 5000 | R10: =E10+F10+G10+H10+I10+J10+K10+L10+M10+N10+O10+P10+Q10 -> 5000
A11: =A10+1 -> 9 | B11: 000018 | C11: Ade Prihadi | D11: CG | E11: 0 | R11: =E11+F11+G11+H11+I11+J11+K11+L11+M11+N11+O11+P11+Q11 -> 0
A12: =A11+1 -> 10 | B12: 000019 | C12: Ade Sugandi | D12: - | E12: 0 | R12: =E12+F12+G12+H12+I12+J12+K12+L12+M12+N12+O12+P12+Q12 -> 0
A13: =A12+1 -> 11 | B13: 000020 | C13: Adhitama Rama | D13: PHP | E13: 0 | R13: =E13+F13+G13+H13+I13+J13+K13+L13+M13+N13+O13+P13+Q13 -> 0
A14: =A13+1 -> 12 | B14: 000021 | C14: Adi Iman Patria | D14: HC&L | E14: 0 | R14: =E14+F14+G14+H14+I14+J14+K14+L14+M14+N14+O14+P14+Q14 -> 0
A15: =A14+1 -> 13 | B15: 000025 | C15: Aditia Warman | D15: - | E15: 0 | R15: =E15+F15+G15+H15+I15+J15+K15+L15+M15+N15+O15+P15+Q15 -> 0
A16: =A15+1 -> 14 | B16: 000026 | C16: ADITYA TRISANDHYA PRAMANA | D16: STA | E16: 5000 | R16: =E16+F16+G16+H16+I16+J16+K16+L16+M16+N16+O16+P16+Q16 -> 5000
A17: =A16+1 -> 15 | B17: 000027 | C17: Afrizal | D17: - | E17: 0 | R17: =E17+F17+G17+H17+I17+J17+K17+L17+M17+N17+O17+P17+Q17 -> 0
A18: =A17+1 -> 16 | B18: 000029 | C18: Agung Budi Arnanto | D18: PU | E18: 0 | R18: =E18+F18+G18+H18+I18+J18+K18+L18+M18+N18+O18+P18+Q18 -> 0
A19: =A18+1 -> 17 | B19: 000030 | C19: Agung Prihanto | D19: HCTIO | E19: 5000 | F19: -5000 | R19: =E19+F19+G19+H19+I19+J19+K19+L19+M19+N19+O19+P19+Q19 -> 0
A20: =A19+1 -> 18 | B20: 000031 | C20: Agung Wicaksono | D20: SB | E20: 0 | R20: =E20+F20+G20+H20+I20+J20+K20+L20+M20+N20+O20+P20+Q20 -> 0
A21: =A20+1 -> 19 | B21: 000032 | C21: Agus Siswoko | D21: PRB | E21: 0 | R21: =E21+F21+G21+H21+I21+J21+K21+L21+M21+N21+O21+P21+Q21 -> 0
A22: =A21+1 -> 20 | B22: 000033 | C22: Agus Salim | D22: PRB | E22: 0 | R22: =E22+F22+G22+H22+I22+J22+K22+L22+M22+N22+O22+P22+Q22 -> 0
A23: =A22+1 -> 21 | B23: 000037 | C23: Agustang | D23: BM | E23: 0 | R23: =E23+F23+G23+H23+I23+J23+K23+L23+M23+N23+O23+P23+Q23 -> 0
A24: =A23+1 -> 22 | B24: 000039 | C24: Ahmad Aliyudin | D24: MHC | E24: 0 | R24: =E24+F24+G24+H24+I24+J24+K24+L24+M24+N24+O24+P24+Q24 -> 0
A25: =A24+1 -> 23 | B25: 000042 | C25: Ahmad Rifaid | D25: PR | E25: 0 | R25: =E25+F25+G25+H25+I25+J25+K25+L25+M25+N25+O25+P25+Q25 -> 0
A26: =A25+1 -> 24 | B26: 000043 | C26: Ahmad Sariful Anwar | D26: PRB | E26: 0 | R26: =E26+F26+G26+H26+I26+J26+K26+L26+M26+N26+O26+P26+Q26 -> 0
A27: =A26+1 -> 25 | B27: 000044 | C27: AHMAD YUNUS | D27: PU | E27: 5000 | R27: =E27+F27+G27+H27+I27+J27+K27+L27+M27+N27+O27+P27+Q27 -> 5000
A28: =A27+1 -> 26 | B28: 000045 | C28: AHMAD ZAKKY | D28: MHC | E28: 0 | R28: =E28+F28+G28+H28+I28+J28+K28+L28+M28+N28+O28+P28+Q28 -> 0
A29: =A28+1 -> 27 | B29: 000048 | C29: AKHMAD MULIADDIN | D29: PBC | E29: 5000 | R29: =E29+F29+G29+H29+I29+J29+K29+L29+M29+N29+O29+P29+Q29 -> 5000
A30: =A29+1 -> 28 | B30: 000052 | C30: Alfonsus Susilarso | D30: SV | E30: 0 | R30: =E30+F30+G30+H30+I30+J30+K30+L30+M30+N30+O30+P30+Q30 -> 0
A31: =A30+1 -> 29 | B31: 000053 | C31: ALI AKBAR BASO | D31: TP | E31: 200000 | M31: 200000 | R31: =E31+F31+G31+H31+I31+J31+K31+L31+M31+N31+O31+P31+Q31 -> 400000
A32: =A31+1 -> 30 | B32: 000056 | C32: Alim Saadi | D32: R&P | E32: 5000 | R32: =E32+F32+G32+H32+I32+J32+K32+L32+M32+N32+O32+P32+Q32 -> 5000
A33: =A32+1 -> 31 | B33: 000059 | C33: ANDI ARDI ABDULLAH | D33: MKSC | E33: 5000 | R33: =E33+F33+G33+H33+I33+J33+K33+L33+M33+N33+O33+P33+Q33 -> 5000
A34: =A33+1 -> 32 | B34: 000060 | C34: Andi Arman | D34: SV | E34: 5000 | R34: =E34+F34+G34+H34+I34+J34+K34+L34+M34+N34+O34+P34+Q34 -> 5000
A35: =A34+1 -> 33 | B35: 000062 | C35: ANDI LAMAPPASESSU | D35: PSMMO | E35: 5000 | R35: =E35+F35+G35+H35+I35+J35+K35+L35+M35+N35+O35+P35+Q35 -> 5000
A36: =A35+1 -> 34 | B36: 000064 | C36: ANDI NURALIM KAMAL | D36: PRB | E36: 5000 | R36: =E36+F36+G36+H36+I36+J36+K36+L36+M36+N36+O36+P36+Q36 -> 5000
A37: =A36+1 -> 35 | B37: 000065 | C37: ANDI P. SIAGIAN | D37: BN | E37: 5000 | R37: =E37+F37+G37+H37+I37+J37+K37+L37+M37+N37+O37+P37+Q37 -> 5000
A38: =A37+1 -> 36 | B38: 000067 | C38: ANDRI SURYAWAN | D38: LC | E38: 5000 | R38: =E38+F38+G38+H38+I38+J38+K38+L38+M38+N38+O38+P38+Q38 -> 5000
A39: =A38+1 -> 37 | B39: 000070 | C39: Anita Magdalena | D39: SPI | E39: 5000 | R39: =E39+F39+G39+H39+I39+J39+K39+L39+M39+N39+O39+P39+Q39 -> 5000
A40: =A39+1 -> 38 | B40: 000071 | C40: ANOGI AKBAR ALI | D40: PSMMO | E40: 5000 | R40: =E40+F40+G40+H40+I40+J40+K40+L40+M40+N40+O40+P40+Q40 -> 5000
...

Sheet Simpanan Khusus
A1: NO. | B1: NO. ANGGOTA | C1: NAMA ANGGOTA | D1: UNIT KERJA | E1: SALDO SIMPANAN KHUSUS 2024 | F1: SALDO 2025 | R1: SALDO 2025
F2: Januari | G2: Februari | H2: Maret | I2: April | J2: Mei | K2: Juni | L2: Juli | M2: Agustus | N2: September | O2: Oktober | P2: November | Q2: Desember
A3: 1 | B3: 000001 | C3: A'AN AGUS FIRMANSYAH | D3: SBC | E3: 0 | R3: =E3+F3+G3+H3+I3+J3+K3+L3+M3+N3+O3+P3+Q3 -> 0
A4: 2 | B4: 000002 | C4: Abdul Ghofar | D4: DOC | E4: 0 | R4: =E4+F4+G4+H4+I4+J4+K4+L4+M4+N4+O4+P4+Q4 -> 0
A5: 3 | B5: 000003 | C5: Abdul Hadi | E5: 0 | R5: =E5+F5+G5+H5+I5+J5+K5+L5+M5+N5+O5+P5+Q5 -> 0
A6: 4 | B6: 000006 | C6: ABUKASIM USMAN | D6: SB | E6: 0 | R6: =E6+F6+G6+H6+I6+J6+K6+L6+M6+N6+O6+P6+Q6 -> 0
A7: 5 | B7: 000009 | C7: Achmad | D7: PUMA | E7: 795000 | P7: -795000 | R7: =E7+F7+G7+H7+I7+J7+K7+L7+M7+N7+O7+P7+Q7 -> 0
A8: 6 | B8: 000013 | C8: AKHMAD MUSLIM | D8: HCTIO | E8: 37500 | O8: -37500 | R8: =E8+F8+G8+H8+I8+J8+K8+L8+M8+N8+O8+P8+Q8 -> 0
A9: 7 | B9: 000014 | C9: Achmad Suseno | D9: R&P | E9: 0 | R9: =E9+F9+G9+H9+I9+J9+K9+L9+M9+N9+O9+P9+Q9 -> 0
A10: 8 | B10: 000015 | C10: ACHMAD TAWAKKAL RAMPA | D10: DOC | E10: 0 | R10: =E10+F10+G10+H10+I10+J10+K10+L10+M10+N10+O10+P10+Q10 -> 0
A11: 9 | B11: 000018 | C11: Ade Prihadi | D11: CG | E11: 0 | R11: =E11+F11+G11+H11+I11+J11+K11+L11+M11+N11+O11+P11+Q11 -> 0
A12: 10 | B12: 000019 | C12: Ade Sugandi | D12: - | E12: 100000 | R12: =E12+F12+G12+H12+I12+J12+K12+L12+M12+N12+O12+P12+Q12 -> 100000
A13: 11 | B13: 000020 | C13: Adhitama Rama | D13: PHP | E13: 0 | R13: =E13+F13+G13+H13+I13+J13+K13+L13+M13+N13+O13+P13+Q13 -> 0
A14: 12 | B14: 000021 | C14: Adi Iman Patria | D14: HC&L | E14: 0 | R14: =E14+F14+G14+H14+I14+J14+K14+L14+M14+N14+O14+P14+Q14 -> 0
A15: 13 | B15: 000025 | C15: Aditia Warman | D15: - | E15: 0 | R15: =E15+F15+G15+H15+I15+J15+K15+L15+M15+N15+O15+P15+Q15 -> 0
A16: 14 | B16: 000026 | C16: ADITYA TRISANDHYA PRAMANA | D16: STA | E16: 0 | R16: =E16+F16+G16+H16+I16+J16+K16+L16+M16+N16+O16+P16+Q16 -> 0
A17: 15 | B17: 000027 | C17: Afrizal | D17: - | E17: 0 | R17: =E17+F17+G17+H17+I17+J17+K17+L17+M17+N17+O17+P17+Q17 -> 0
A18: 16 | B18: 000029 | C18: Agung Budi Arnanto | D18: PU | E18: 0 | R18: =E18+F18+G18+H18+I18+J18+K18+L18+M18+N18+O18+P18+Q18 -> 0
A19: 17 | B19: 000030 | C19: Agung Prihanto | D19: HCTIO | E19: 347500 | F19: -347500 | R19: =E19+F19+G19+H19+I19+J19+K19+L19+M19+N19+O19+P19+Q19 -> 0
A20: 18 | B20: 000031 | C20: Agung Wicaksono | D20: SB | E20: 0 | R20: =E20+F20+G20+H20+I20+J20+K20+L20+M20+N20+O20+P20+Q20 -> 0
A21: 19 | B21: 000032 | C21: Agus Siswoko | D21: PRB | E21: 0 | R21: =E21+F21+G21+H21+I21+J21+K21+L21+M21+N21+O21+P21+Q21 -> 0
A22: 20 | B22: 000033 | C22: Agus Salim | D22: PRB | E22: 0 | R22: =E22+F22+G22+H22+I22+J22+K22+L22+M22+N22+O22+P22+Q22 -> 0
A23: 21 | B23: 000037 | C23: Agustang | D23: BM | E23: 0 | R23: =E23+F23+G23+H23+I23+J23+K23+L23+M23+N23+O23+P23+Q23 -> 0
A24: 22 | B24: 000039 | C24: Ahmad Aliyudin | D24: MHC | E24: 0 | R24: =E24+F24+G24+H24+I24+J24+K24+L24+M24+N24+O24+P24+Q24 -> 0
A25: 23 | B25: 000042 | C25: Ahmad Rifaid | D25: PR | E25: 0 | R25: =E25+F25+G25+H25+I25+J25+K25+L25+M25+N25+O25+P25+Q25 -> 0
A26: 24 | B26: 000043 | C26: Ahmad Sariful Anwar | D26: PRB | E26: 0 | R26: =E26+F26+G26+H26+I26+J26+K26+L26+M26+N26+O26+P26+Q26 -> 0
A27: 25 | B27: 000044 | C27: AHMAD YUNUS | D27: PU | E27: 535000 | R27: =E27+F27+G27+H27+I27+J27+K27+L27+M27+N27+O27+P27+Q27 -> 535000
A28: 26 | B28: 000045 | C28: AHMAD ZAKKY | D28: MHC | E28: 0 | R28: =E28+F28+G28+H28+I28+J28+K28+L28+M28+N28+O28+P28+Q28 -> 0
A29: 27 | B29: 000048 | C29: AKHMAD MULIADDIN | D29: PBC | E29: 0 | R29: =E29+F29+G29+H29+I29+J29+K29+L29+M29+N29+O29+P29+Q29 -> 0
A30: 28 | B30: 000052 | C30: Alfonsus Susilarso | D30: SV | E30: 0 | R30: =E30+F30+G30+H30+I30+J30+K30+L30+M30+N30+O30+P30+Q30 -> 0
A31: 29 | B31: 000053 | C31: ALI AKBAR BASO | D31: TP | E31: 0 | R31: =E31+F31+G31+H31+I31+J31+K31+L31+M31+N31+O31+P31+Q31 -> 0
... A37: 35 | B37: 000065 | C37: ANDI P. SIAGIAN | D37: BN | E37: 0 | R37: =E37+F37+G37+H37+I37+J37+K37+L37+M37+N37+O37+P37+Q37 -> 0
A38: 36 | B38: 000067 | C38: ANDRI SURYAWAN | D38: LC | E38: 650000 | G38: 8333 | I38: 8333 | J38: 25000 | K38: 8333 | L38: 8333 | M38: 8333 | N38: 8333 | O38: =250000+8333 -> 258333 | P38: 8333 | Q38: 8333 | R38: =E38+F38+G38+H38+I38+J38+K38+L38+M38+N38+O38+P38+Q38 -> 999997
A39: 37 | B39: 000070 | C39: Anita Magdalena | D39: SPI | E39: 375000 | R39: =E39+F39+G39+H39+I39+J39+K39+L39+M39+N39+O39+P39+Q39 -> 375000
A40: 38 | B40: 000071 | C40: ANOGI AKBAR ALI | D40: PSMMO | E40: 50000 | R40: =E40+F40+G40+H40+I40+J40+K40+L40+M40+N40+O40+P40+Q40 -> 50000
A41: 39 | B41: 000072 | C41: Antong Goli | D41: PK | E41: 0 | R41: =E41+F41+G41+H41+I41+J41+K41+L41+M41+N41+O41+P41+Q41 -> 0
A42: 40 | B42: 000075 | C42: Aquarius Setiawan | D42: SBC | E42: 0 | R42: =E42+F42+G42+H42+I42+J42+K42+L42+M42+N42+O42+P42+Q42 -> 0
A43: 41 | B43: 000076 | C43: ARDHIAN BUDI SULISTIYO | D43: SBU MNO | E43: 0 | R43: =E43+F43+G43+H43+I43+J43+K43+L43+M43+N43+O43+P43+Q43 -> 0
A44: 42 | B44: 000081 | C44: ARIEF BUDI PERMANA | D44: DOK | E44: 0 | R44: =E44+F44+G44+H44+I44+J44+K44+L44+M44+N44+O44+P44+Q44 -> 0
A45: 43 | B45: 000083 | C45: Arief Nurtjahjo | D45: BM | E45: 0 | R45: =E45+F45+G45+H45+I45+J45+K45+L45+M45+N45+O45+P45+Q45 -> 0
...

Sheet Simpanan Sukarela
A1: SIMPANAN SUKARELA 2025
A3: NO. | B3: NO. ANGGOTA | C3: NAMA ANGGOTA | D3: UNIT KERJA | E3: SIMPANAN SUKARELA | F3: SIMPANAN SUKARELA 2025 | R3: SALDO 2025
F4: JANUARI | G4: FEBRUARI | H4: MARET | I4: APRIL | J4: MEI | K4: JUNI | L4: JULI | M4: AGUSTUS | N4: SEPTEMBER | O4: OKTOBER | P4: NOVEMBER | Q4: DESEMBER
A5: 1 | B5: 000001 | C5: A'AN AGUS FIRMANSYAH | D5: SBC | E5: 1997222 | R5: =E5+F5+G5+H5+I5+J5+K5+L5+M5+N5+O5+P5+Q5 -> 1997222
A6: 2 | B6: 000002 | C6: Abdul Ghofar | D6: DOC | E6: 0.40666906 | R6: =E6+F6+G6+H6+I6+J6+K6+L6+M6+N6+O6+P6+Q6 -> 0.40666906
A7: 3 | B7: 000003 | C7: Abdul Hadi | E7: 6155 | R7: =E7+F7+G7+H7+I7+J7+K7+L7+M7+N7+O7+P7+Q7 -> 6155
A8: 4 | B8: 000006 | C8: Abu Kasim Usman | D8: SB | E8: 1217315.7 | R8: =E8+F8+G8+H8+I8+J8+K8+L8+M8+N8+O8+P8+Q8 -> 1217315.7
A9: 5 | B9: 000009 | C9: Achmad | D9: PUMA | E9: 2229525.3 | P9: -2651746 | R9: =E9+F9+G9+H9+I9+J9+K9+L9+M9+N9+O9+P9+Q9 -> -422220.71
A10: 6 | B10: 000013 | C10: AKHMAD MUSLIM | D10: HCTIO | E10: 15062213 | O10: -15861822 | R10: =E10+F10+G10+H10+I10+J10+K10+L10+M10+N10+O10+P10+Q10 -> -799609.19
A11: 7 | B11: 000014 | C11: Achmad Suseno | D11: R&P | E11: 250663.25 | R11: =E11+F11+G11+H11+I11+J11+K11+L11+M11+N11+O11+P11+Q11 -> 250663.25
A12: 8 | B12: 000015 | C12: ACHMAD TAWAKKAL RAMPA | D12: DOC | E12: 5114337.2 | R12: =E12+F12+G12+H12+I12+J12+K12+L12+M12+N12+O12+P12+Q12 -> 5114337.2
A13: 9 | B13: 000018 | C13: Ade Prihadi | D13: CG | E13: 655986 | R13: =E13+F13+G13+H13+I13+J13+K13+L13+M13+N13+O13+P13+Q13 -> 655986
A14: 10 | B14: 000019 | C14: Ade Sugandi | D14: - | E14: 214116.94 | R14: =E14+F14+G14+H14+I14+J14+K14+L14+M14+N14+O14+P14+Q14 -> 214116.94
A15: 11 | B15: 000020 | C15: Adhitama Rama | D15: PHP | E15: 178433 | R15: =E15+F15+G15+H15+I15+J15+K15+L15+M15+N15+O15+P15+Q15 -> 178433
A16: 12 | B16: 000021 | C16: Adi Iman Patria | D16: HC&L | E16: -0.30986904 | R16: =E16+F16+G16+H16+I16+J16+K16+L16+M16+N16+O16+P16+Q16 -> -0.30986904
A17: 13 | B17: 000025 | C17: Aditia Warman | D17: - | E17: 2245019 | R17: =E17+F17+G17+H17+I17+J17+K17+L17+M17+N17+O17+P17+Q17 -> 2245019
A18: 14 | B18: 000026 | C18: ADITYA TRISANDHYA PRAMANA | D18: STA | E18: 4257094.7 | R18: =E18+F18+G18+H18+I18+J18+K18+L18+M18+N18+O18+P18+Q18 -> 4257094.7
A19: 15 | B19: 000027 | C19: Afrizal | D19: - | E19: 131136.88 | R19: =E19+F19+G19+H19+I19+J19+K19+L19+M19+N19+O19+P19+Q19 -> 131136.88
A20: 16 | B20: 000029 | C20: Agung Budi Arnanto | D20: PU | E20: -0.24917701 | R20: =E20+F20+G20+H20+I20+J20+K20+L20+M20+N20+O20+P20+Q20 -> -0.24917701
A21: 17 | B21: 000030 | C21: Agung Prihanto | D21: HCTIO | E21: 11842162 | F21: -11842162 | R21: =E21+F21+G21+H21+I21+J21+K21+L21+M21+N21+O21+P21+Q21 -> -0.35066185
A22: 18 | B22: 000031 | C22: Agung Wicaksono | D22: SB | E22: 944319.45 | R22: =E22+F22+G22+H22+I22+J22+K22+L22+M22+N22+O22+P22+Q22 -> 944319.45
A23: 19 | B23: 000032 | C23: Agus Siswoko | D23: PRB | E23: 6374025 | R23: =E23+F23+G23+H23+I23+J23+K23+L23+M23+N23+O23+P23+Q23 -> 6374025
A24: 20 | B24: 000033 | C24: Agus Salim | D24: PRB | E24: 93974.008 | R24: =E24+F24+G24+H24+I24+J24+K24+L24+M24+N24+O24+P24+Q24 -> 93974.008
A25: 21 | B25: 000037 | C25: Agustang | D25: BM | E25: 10257.863 | R25: =E25+F25+G25+H25+I25+J25+K25+L25+M25+N25+O25+P25+Q25 -> 10257.863
A26: 22 | B26: 000039 | C26: Ahmad Aliyudin | D26: MHC | E26: -0.26117866 | R26: =E26+F26+G26+H26+I26+J26+K26+L26+M26+N26+O26+P26+Q26 -> -0.26117866
A27: 23 | B27: 000042 | C27: Ahmad Rifaid | D27: PR | E27: 0.10110832 | R27: =E27+F27+G27+H27+I27+J27+K27+L27+M27+N27+O27+P27+Q27 -> 0.10110832
A28: 24 | B28: 000043 | C28: Ahmad Sariful Anwar | D28: PRB | E28: 91043.699 | R28: =E28+F28+G28+H28+I28+J28+K28+L28+M28+N28+O28+P28+Q28 -> 91043.699
A29: 25 | B29: 000044 | C29: Ahmad Yunus | D29: PU | E29: 1783497.3 | L29: -235552.22 | R29: =E29+F29+G29+H29+I29+J29+K29+L29+M29+N29+O29+P29+Q29 -> 1547945.1
A30: 26 | B30: 000045 | C30: AHMAD ZAKKY | D30: MHC | E30: 168972.28 | R30: =E30+F30+G30+H30+I30+J30+K30+L30+M30+N30+O30+P30+Q30 -> 168972.28
A31: 27 | B31: 000048 | C31: Akhmad Muliaddin | D31: PBC | E31: 3875093.4 | R31: =E31+F31+G31+H31+I31+J31+K31+L31+M31+N31+O31+P31+Q31 -> 3875093.4
A32: 28 | B32: 000052 | C32: Alfonsus Susilarso | D32: SV | E32: 758204 | R32: =E32+F32+G32+H32+I32+J32+K32+L32+M32+N32+O32+P32+Q32 -> 758204
A33: 29 | B33: 000053 | C33: ALI AKBAR BASO | D33: TP | E33: 287113.34 | R33: =E33+F33+G33+H33+I33+J33+K33+L33+M33+N33+O33+P33+Q33 -> 287113.34
A34: 30 | B34: 000056 | C34: Alim Saadi | D34: R&P | E34: 19727391 | R34: =E34+F34+G34+H34+I34+J34+K34+L34+M34+N34+O34+P34+Q34 -> 19727391
A35: 31 | B35: 000059 | C35: Andi Ardi Abdullah | D35: MKSC | E35: 6717668.7 | R35: =E35+F35+G35+H35+I35+J35+K35+L35+M35+N35+O35+P35+Q35 -> 6717668.7
A36: 32 | B36: 000060 | C36: Andi Arman | D36: SV | E36: 2979690.5 | R36: =E36+F36+G36+H36+I36+J36+K36+L36+M36+N36+O36+P36+Q36 -> 2979690.5
A37: 33 | B37: 000062 | C37: ANDI LAMAPPASESSU | D37: PSMMO | E37: 8565906.7 | R37: =E37+F37+G37+H37+I37+J37+K37+L37+M37+N37+O37+P37+Q37 -> 8565906.7
A38: 34 | B38: 000064 | C38: ANDI NURALIM KAMAL | D38: PRB | E38: 3956525.8 | R38: =E38+F38+G38+H38+I38+J38+K38+L38+M38+N38+O38+P38+Q38 -> 3956525.8
A39: 35 | B39: 000065 | C39: ANDI P. SIAGIAN | D39: BN | E39: 3299412.1 | R39: =E39+F39+G39+H39+I39+J39+K39+L39+M39+N39+O39+P39+Q39 -> 3299412.1
A40: 36 | B40: 000067 | C40: ANDRI SURYAWAN | D40: LC | E40: 2945305.3 | R40: =E40+F40+G40+H40+I40+J40+K40+L40+M40+N40+O40+P40+Q40 -> 2945305.3
A41: 37 | B41: 000070 | C41: Anita Magdalena | D41: SPI | E41: 4081046.1 | R41: =E41+F41+G41+H41+I41+J41+K41+L41+M41+N41+O41+P41+Q41 -> 4081046.1
...

Sheet Simpanan Sukarela Berjangka
A1: No | B1: Nama | C1: Tanggal Penyetoran | D1: Tanggal Jatuh Tempo | E1: Penyertaan Modal | F1: Imbal Hasil | G1: Tenor | H1: Imbal Hasil Kotor | I1: PPh 4 Ayat 2 | J1: Imbal Hasil Bersih | K1: Total Setor + Imbal Hasil Bersih | L1: Imbal Bagi Hasil dikembaliakan 2026
A2: 1 | B2: ANOGI AKABR ALI | C2: 45840 | D2: 46024 | E2: 75000000 | F2: 0.075 | G2: 6 | H2: =E2*F2 -> 5625000 | I2: =H2*10% -> 562500 | J2: =H2-I2 -> 5062500 | K2: =E2+J2 -> 80062500
A3: 2 | B3: ROSALINA AMRAN | C3: 45840 | D3: 46024 | E3: 74000000 | F3: 0.07 | G3: 6 | H3: =E3*F3 -> 5180000 | I3: =H3*10% -> 518000 | J3: =H3-I3 -> 4662000 | K3: =E3+J3 -> 78662000
A4: 3 | B4: MUHAMMAD ADITYO NUGROHO | C4: 45840 | D4: 46024 | E4: 55000000 | F4: 0.07 | G4: 6 | H4: =E4*F4 -> 3850000 | I4: =H4*10% -> 385000 | J4: =H4-I4 -> 3465000 | K4: =E4+J4 -> 58465000
A5: 4 | B5: RIANA PATRICIA | C5: 45841 | D5: 46025 | E5: 100000000 | F5: 0.075 | G5: 6 | H5: =E5*F5 -> 7500000 | I5: =H5*10% -> 750000 | J5: =H5-I5 -> 6750000 | K5: =E5+J5 -> 106750000
A6: 5 | B6: WARINI | C6: 45841 | D6: 46025 | E6: 25000000 | F6: 0.065 | G6: 6 | H6: =E6*F6 -> 1625000 | I6: =H6*10% -> 162500 | J6: =H6-I6 -> 1462500 | K6: =E6+J6 -> 26462500
B7: SUGENG YULIANTO | C7: 45897 | D7: 46246 | E7: 200000000 | F7: 0.07 | G7: 12 | H7: =E7*F7 -> 14000000 | I7: =H7*10% -> 1400000 | J7: =H7-I7 -> 12600000 | K7: =E7+J7 -> 212600000
A8: 6 | B8: MUHAMAD SODIK | C8: 45841 | D8: 46025 | E8: 75000000 | F8: 0.075 | G8: 6 | H8: =E8*F8 -> 5625000 | I8: =H8*10% -> 562500 | J8: =H8-I8 -> 5062500 | K8: =E8+J8 -> 80062500
A9: 7 | B9: ANNISYAH FAZRIN | C9: 45938 | D9: 46022 | E9: 250000000 | F9: 0.044444444 | G9: 3 | H9: =E9*F9 -> 11111111 | I9: =H9*10% -> 1111111.1 | J9: =H9-I9 -> 10000000 | K9: =E9+J9 -> 2.6e+08
A10: 8 | B10: MARIYANA ASTRI FANDANI | C10: 45954 | D10: 46318 | E10: 15000000 | F10: 0.07 | G10: 12 | H10: =E10*F10 -> 1050000 | I10: =H10*10% -> 105000 | J10: =H10-I10 -> 945000 | K10: =E10+J10 -> 15945000
A11: 9 | B11: ROSALINA AMRAN | C11: 45954 | D11: 46318 | E11: 35000000 | F11: 0.07 | G11: 12 | H11: =E11*F11 -> 2450000 | I11: =H11*10% -> 245000 | J11: =H11-I11 -> 2205000 | K11: =E11+J11 -> 37205000
A12: 10 | B12: RIMA NOVEDIA BANGUN | C12: 45957 | D12: 46318 | E12: 100000000 | F12: 0.07 | G12: 12 | H12: =E12*F12 -> 7000000 | I12: =H12*10% -> 700000 | J12: =H12-I12 -> 6300000 | K12: =E12+J12 -> 106300000
A13: Total | B13: Total | E13: =SUM(E2:E12) -> 1004000000 | H13: =SUM(H2:H12) -> 65016111 | I13: =SUM(I2:I12) -> 6501611.1 | J13: =SUM(J2:J12) -> 58514500 | K13: =SUM(K2:K12) -> 1.0625145e+09 | L13: =SUM(L2:L12) -> 0
E14: 1004000000 | H14: 65016111 | J14: 58514500
E15: =E13-E14 -> 0 | H15: =H13-H14 -> 0.1 | J15: =J13-J14 -> -0.0099999979
