Workbook

Sheet REKAP PIUTANG BANK
B1: BANK MANDIRI
A2: No | B2: Nama | D2: Piutang 2023 | E2: Angsuran | R2: PEMBAYARAN TAHUN 2025
E3: Januari | F3: Februari | G3: Maret | H3: April | I3: Mei | J3: Juni | K3: Juli | L3: Agustus | M3: September | N3: Oktober | O3: November | P3: Desember | Q3: TOTAL PEMBAYARAN 2024 | R3: Sisa Hutang 2024 | S3: JANUARI | T3: FEBRUARI | U3: MARET | V3: APRIL | W3: MEI | X3: JUNI | Y3: JULI | Z3: AGUSTUS | AA3: SEPTEMBER | AB3: OKTOBER | AC3: NOVEMBER | AD3: DESEMBER | AE3: Piutang
A4: 1 | B4: Wawan Priya Widyanta | D4: ='Piutang Bank Mandiri -24'!F213 -> 270594142 | E4: ='Piutang Bank Mandiri -24'!E214 -> 4404185 | F4: ='Piutang Bank Mandiri -24'!E215 -> 4444373 | G4: ='Piutang Bank Mandiri -24'!E216 -> 4484928 | H4: ='Piutang Bank Mandiri -24'!E217 -> 4525853 | I4: ='Piutang Bank Mandiri -24'!E218 -> 4567152 | J4: ='Piutang Bank Mandiri -24'!E219 -> 4608827 | K4: ='Piutang Bank Mandiri -24'!E220 -> 4650883 | L4: ='Piutang Bank Mandiri -24'!E221 -> 4693322 | M4: ='Piutang Bank Mandiri -24'!E222 -> 4736148 | N4: ='Piutang Bank Mandiri -24'!E223 -> 4779366 | O4: ='Piutang Bank Mandiri -24'!E224 -> 4822977 | P4: ='Piutang Bank Mandiri -24'!E225 -> 4866987 | Q4: =SUM(E4:P4) -> 55585001 | R4: =D4-E4-F4-G4-H4-I4-J4-K4-L4-M4-N4-O4-P4 -> 215009141 | S4: 4911398 | T4: 4956215 | U4: 5001440 | V4: 5047078 | W4: 5093133 | X4: 5139608 | Y4: 5186507 | Z4: 5233834 | AA4: 5281592 | AB4: 5329787 | AC4: 5378421 | AD4: 5427499 | AE4: =R4-S4-T4-U4-V4-W4-X4-Y4-Z4-AA4-AB4-AC4-AD4 -> 153022629
A5: 2 | B5: Sumartini | D5: ='Piutang Bank Mandiri -24'!F143 -> 226855344 | E5: {=TRANSPOSE('Piutang Bank Mandiri -24'!E144:E155)} -> 3428630 | F5: 3459917 | G5: 3491488 | H5: 3523348 | I5: 3555499 | J5: 3587943 | K5: 3620683 | L5: 3653721 | M5: 3687062 | N5: 3720706 | O5: 3754657 | P5: 3788919 | Q5: =SUM(E5:P5) -> 43272573 | R5: =D5-E5-F5-G5-H5-I5-J5-K5-L5-M5-N5-O5-P5 -> 183582771 | S5: 3823493 | T5: 3858382 | U5: 3893590 | V5: 3929119 | W5: 3964972 | X5: 4001152 | Y5: 4037663 | Z5: 4074506 | AA5: 4111686 | AB5: 4149205 | AC5: 4187067 | AD5: 4225274 | AE5: =R5-S5-T5-U5-V5-W5-X5-Y5-Z5-AA5-AB5-AC5-AD5 -> 135326662
A6: 3 | B6: IRWANTO | D6: ='Piutang Bank Mandiri -24'!F45 -> 141784587 | E6: {=TRANSPOSE('Piutang Bank Mandiri -24'!E46:E57)} -> 2142894 | F6: 2162448 | G6: 2182180 | H6: 2202093 | I6: 2222187 | J6: 2242464 | K6: 2262927 | L6: 2283576 | M6: 2304413 | N6: 2325441 | O6: 2346661 | P6: 2368074 | Q6: =SUM(E6:P6) -> 27045358 | R6: =D6-E6-F6-G6-H6-I6-J6-K6-L6-M6-N6-O6-P6 -> 114739229 | S6: 2389683 | T6: 2411489 | U6: 2433494 | V6: 2455699 | W6: 2478107 | X6: 2500720 | Y6: 2523539 | Z6: 2546567 | AA6: 2569804 | AB6: 2593253 | AC6: 2616917 | AD6: 2640796 | AE6: =R6-S6-T6-U6-V6-W6-X6-Y6-Z6-AA6-AB6-AC6-AD6 -> 84579161
A7: 4 | B7: Rochmansyah | D7: ='Piutang Bank Mandiri -24'!F107 -> 69702128 | E7: {=TRANSPOSE('Piutang Bank Mandiri -24'!E108:E119)} -> 3808969 | F7: 3843726 | G7: 3878800 | H7: 3914194 | I7: 3949911 | J7: 3985954 | K7: 4022326 | L7: 4059030 | M7: 4096068 | N7: 4133445 | O7: 4171163 | P7: 4209224 | Q7: =SUM(E7:P7) -> 48072810 | R7: =D7-E7-F7-G7-H7-I7-J7-K7-L7-M7-N7-O7-P7 -> 21629318 | S7: 4247634 | T7: 4286393 | U7: 4325507 | V7: 4364977 | W7: 4404808 | X7: 0 | Y7: 0 | Z7: 0 | AA7: 0 | AE7: =R7-S7-T7-U7-V7-W7-X7-Y7-Z7-AA7-AB7 -> -1
A8: 5 | B8: M. Sofyan | D8: ='Piutang Bank Mandiri -24'!F245 -> 16574269 | E8: {=TRANSPOSE('Piutang Bank Mandiri -24'!E246:E251)} -> 2700032 | F8: 2724669 | G8: 2749532 | H8: 2774621 | I8: 2799940 | J8: 2825475 | Q8: =SUM(E8:P8) -> 16574269 | R8: LUNAS | Y8: 0 | Z8: 0 | AA8: 0 | AE8: LUNAS
A9: 6 | B9: Eva Sintauli Saragih | D9: ='Piutang Bank Mandiri -24'!F14 -> 287816220 | E9: {=TRANSPOSE('Piutang Bank Mandiri -24'!E15:E26)} -> 4247034 | F9: 4285788 | G9: 4324896 | H9: 4364360 | I9: 4404185 | J9: 4444373 | K9: 4484928 | L9: 4525853 | M9: 4567152 | N9: 4608827 | O9: 4650883 | P9: 4693322 | Q9: =SUM(E9:P9) -> 53601601 | R9: =D9-E9-F9-G9-H9-I9-J9-K9-L9-M9-N9-O9-P9 -> 234214619 | S9: 4736148 | T9: 4779366 | U9: 4822977 | V9: 4866987 | W9: 4911398 | X9: 4956215 | Y9: 5001440 | Z9: 5047078 | AA9: 5093133 | AB9: 5139608 | AC9: 5186507 | AD9: 5233834 | AE9: =R9-S9-T9-U9-V9-W9-X9-Y9-Z9-AA9-AB9-AC9-AD9 -> 174439928
A10: 7 | B10: Sukadi Redji | D10: ='Piutang Bank Mandiri -24'!F127 -> 134118469 | E10: {=TRANSPOSE('Piutang Bank Mandiri -24'!E128:E139)} -> 3762876 | F10: 3797213 | G10: 3831862 | H10: 3866828 | I10: 3902113 | J10: 3937720 | K10: 3973651 | L10: 4009911 | M10: 4046501 | N10: 4083426 | O10: 4120687 | P10: 4158288 | Q10: =SUM(E10:P10) -> 47491076 | R10: =D10-E10-F10-G10-H10-I10-J10-K10-L10-M10-N10-O10-P10 -> 86627393 | S10: 4196233 | T10: 4234523 | U10: 4273163 | V10: 4312156 | W10: 4351504 | X10: 4391212 | Y10: 4431282 | Z10: 4471717 | AA10: 4512521 | AB10: 4553698 | AC10: 4595251 | AD10: 4637182 | AE10: =R10-S10-T10-U10-V10-W10-X10-Y10-Z10-AA10-AB10-AC10-AD10 -> 33666951
A11: 8 | B11: Tri Laksono Joeniawan, S.T. | D11: ='Piutang Bank Mandiri -24'!F197 -> 373621854 | E11: {=TRANSPOSE('Piutang Bank Mandiri -24'!E198:E209)} -> 4151393 | F11: 4189274 | G11: 4227502 | H11: 4266078 | I11: 4305006 | J11: 4344289 | K11: 4383930 | L11: 4423934 | M11: 4464302 | N11: 4505039 | O11: 4546147 | P11: 4587631 | Q11: =SUM(E11:P11) -> 52394525 | R11: =D11-E11-F11-G11-H11-I11-J11-K11-L11-M11-N11-O11-P11 -> 321227329 | S11: 4629493 | T11: 4671737 | U11: 4714367 | V11: 4757385 | W11: 4800796 | X11: 4844604 | Y11: 4888811 | Z11: 4933421 | AA11: 4978439 | AB11: 5023867 | AC11: 5069710 | AD11: 5115971 | AE11: =R11-S11-T11-U11-V11-W11-X11-Y11-Z11-AA11-AB11-AC11-AD11 -> 262798728
A12: 9 | B12: Rachmad Kurniawan | D12: ='Piutang Bank Mandiri -24'!F66 -> 136985065 | E12: {=TRANSPOSE('Piutang Bank Mandiri -24'!E67:E78)} -> 3454452 | F12: 3485974 | G12: 3517784 | H12: 3549883 | I12: 3582276 | J12: 3614964 | K12: 3647951 | L12: 3681239 | M12: 3714830 | N12: 3748728 | O12: 3782935 | P12: 3817454 | Q12: =SUM(E12:P12) -> 43598470 | R12: =D12-E12-F12-G12-H12-I12-J12-K12-L12-M12-N12-O12-P12 -> 93386595 | S12: 3852288 | T12: 3887440 | U12: 3922913 | V12: 3958710 | W12: 3994833 | X12: 4031286 | Y12: 4068072 | Z12: 4105193 | AA12: 4142653 | AB12: 4180454 | AC12: 4218601 | AD12: 4257096 | AE12: =R12-S12-T12-U12-V12-W12-X12-Y12-Z12-AA12-AB12-AC12-AD12 -> 44767056
A13: 10 | B13: Rahadi Sigit | D13: ='Piutang Bank Mandiri -24'!F80 -> 10756473 | E13: {=TRANSPOSE('Piutang Bank Mandiri -24'!E81:E92)} -> 852271 | F13: 860048 | G13: 867896 | H13: 875816 | I13: 883807 | J13: 891872 | K13: 900011 | L13: 908223 | M13: 916511 | N13: 924874 | O13: 933313 | P13: 941831 | Q13: =SUM(E13:P13) -> 10756473 | R13: LUNAS | Y13: 0 | Z13: 0 | AA13: 0 | AE13: LUNAS
A14: 11 | B14: Teguh Andani | D14: ='Piutang Bank Mandiri -24'!F166 -> 320438733 | E14: {=TRANSPOSE('Piutang Bank Mandiri -24'!E167:E178)} -> 3949353 | F14: 3985391 | G14: 4021758 | H14: 4058456 | I14: 4095490 | J14: 4132861 | K14: 4170574 | L14: 4208630 | M14: 4247034 | N14: 4285788 | O14: 4324896 | P14: 4364360 | Q14: =SUM(E14:P14) -> 49844591 | R14: =D14-E14-F14-G14-H14-I14-J14-K14-L14-M14-N14-O14-P14 -> 270594142 | S14: 4404185 | T14: 4444373 | U14: 4484928 | V14: 4525853 | W14: 4567152 | X14: 4608827 | Y14: 4650883 | Z14: 4693322 | AA14: 4736148 | AB14: 4779366 | AC14: 4822977 | AD14: 4866987 | AE14: =R14-S14-T14-U14-V14-W14-X14-Y14-Z14-AA14-AB14-AC14-AD14 -> 215009141
A15: 12 | B15: Togap Hidayat Siagian | D15: ='Piutang Bank Mandiri -24'!F181 -> 141881154 | E15: {=TRANSPOSE('Piutang Bank Mandiri -24'!E182:E193)} -> 4859951 | F15: 4904298 | G15: 4949050 | H15: 4994210 | I15: 5039782 | J15: 5085770 | K15: 5132178 | L15: 5179009 | M15: 5226268 | N15: 5273957 | O15: 5322082 | P15: 5370646 | Q15: =SUM(E15:P15) -> 61337201 | R15: =D15-E15-F15-G15-H15-I15-J15-K15-L15-M15-N15-O15-P15 -> 80543953 | S15: 5419653 | T15: 5469108 | U15: 5519013 | V15: 5569374 | W15: 5620195 | X15: 5671479 | Y15: 5723231 | Z15: 5775456 | AA15: 5828157 | AB15: 5881339 | AC15: 5935006 | AD15: 5989163 | AE15: =R15-S15-T15-U15-V15-W15-X15-Y15-Z15-AA15-AB15-AC15-AD15 -> 12142779
A16: 13 | B16: Erry Sanjaya | D16: ='Piutang Bank Mandiri -24'!F6 -> 10567703 | E16: {=TRANSPOSE('Piutang Bank Mandiri -24'!E7:E11)} -> 2075319 | F16: 2094257 | G16: 2113367 | H16: 2132651 | I16: 2152112 | Q16: =SUM(E16:P16) -> 10567706 | R16: =D16-E16-F16-G16-H16-I16-J16-K16-L16-M16-N16-O16-P16 -> -3 | W16: 0 | X16: 0 | Y16: 0 | Z16: 0 | AA16: 0 | AE16: =R16-S16-T16-U16-V16-W16-X16-Y16-Z16-AA16-AB16 -> -3
A17: 14 | B17: Ratna S Rini | D17: ='Piutang Bank Mandiri -24'!F94 -> 155726794 | E17: {=TRANSPOSE('Piutang Bank Mandiri -24'!E95:E103)} -> 7132809 | F17: 7197896 | G17: 7263576 | H17: 7329857 | I17: 7396741 | J17: 7464237 | K17: 7532348 | L17: 7601081 | M17: 96808247 | Q17: =SUM(E17:P17) -> 155726792 | R17: =D17-E17-F17-G17-H17-I17-J17-K17-L17-M17-N17-O17-P17 -> 2 | W17: 0 | X17: 0 | Y17: 0 | Z17: 0 | AA17: 0 | AD17: 0 | AE17: =R17-S17-T17-U17-V17-W17-X17-Y17-Z17-AA17-AB17 -> 2 | AF17: PELUNASAN PINJAMAN AN RATNA S RINI
A18: 15 | B18: Eka Nanda | D18: ='Piutang Bank Mandiri -24'!F229 -> 234774674 | E18: {=TRANSPOSE('Piutang Bank Mandiri -24'!E230:E241)} -> 4130269 | F18: 4167958 | G18: 4205990 | H18: 4244370 | I18: 4283100 | J18: 4322183 | K18: 4361623 | L18: 4401423 | M18: 4441586 | N18: 4482115 | O18: 4523015 | P18: 4564287 | Q18: =SUM(E18:P18) -> 52127919 | R18: =D18-E18-F18-G18-H18-I18-J18-K18-L18-M18-N18-O18-P18 -> 182646755 | S18: 4605936 | T18: 4647966 | U18: 4690378 | V18: 4733178 | W18: 4776368 | X18: 4776368 | Y18: 4863935 | Z18: 4908318 | AA18: 4953106 | AB18: 4998304 | AC18: 5043913 | AD18: 5089939 | AE18: =R18-S18-T18-U18-V18-W18-X18-Y18-Z18-AA18-AB18-AC18-AD18 -> 124559046
A19: 16 | B19: Taufik Hidayat | D19: ='Piutang Bank Mandiri -24'!F159 -> -540450 | Q19: =SUM(E19:P19) -> 0 | R19: =D19-E19-F19-G19-H19-I19-J19-K19-L19-M19-N19-O19-P19 -> -540450 | W19: 0 | Y19: 0 | Z19: 0 | AA19: 0 | AD19: 0 | AE19: =R19-S19-T19-U19-V19-W19-X19-Y19-Z19-AA19-AB19-AC19-AD19 -> -540450
A20: 17 | B20: Guntur Anggriawan | D20: ='Piutang Bank Mandiri -24'!F255 -> 33334677 | Q20: =SUM(E20:P20) -> 0 | R20: =D20-E20-F20-G20-H20-I20-J20-K20-L20-M20-N20-O20-P20 -> 33334677 | W20: 0 | Y20: 0 | Z20: 0 | AA20: 0 | AD20: 0 | AE20: =R20-S20-T20-U20-V20-W20-X20-Y20-Z20-AA20-AB20-AC20-AD20 -> 33334677
A21: 18 | B21: Sudirman | D21: ='Piutang Bank Mandiri -24'!F123 -> 25968558 | Q21: =SUM(E21:P21) -> 0 | R21: =D21-Q21 -> 25968558 | W21: 0 | Y21: 0 | Z21: 0 | AA21: 0 | AC21: =10000000+10000000 -> 20000000 | AD21: 0 | AE21: =R21-S21-T21-U21-V21-W21-X21-Y21-Z21-AA21-AB21-AC21-AD21 -> 5968558
A22: 19 | B22: Indra Permana | D22: ='Piutang Bank Mandiri -24'!F29 -> 225192026 | E22: ='Piutang Bank Mandiri -24'!E30 -> 2962673 | F22: ='Piutang Bank Mandiri -24'!E31 -> 2989708 | G22: ='Piutang Bank Mandiri -24'!E32 -> 3016989 | H22: ='Piutang Bank Mandiri -24'!E33 -> 3044519 | I22: ='Piutang Bank Mandiri -24'!E34 -> 3072300 | J22: ='Piutang Bank Mandiri -24'!E35 -> 3100335 | K22: ='Piutang Bank Mandiri -24'!E36 -> 3128625 | L22: ='Piutang Bank Mandiri -24'!E37 -> 3157174 | M22: ='Piutang Bank Mandiri -24'!E38 -> 3185983 | N22: ='Piutang Bank Mandiri -24'!E39 -> 3215055 | O22: ='Piutang Bank Mandiri -24'!E40 -> 3244393 | P22: ='Piutang Bank Mandiri -24'!E41 -> 3273998 | Q22: =SUM(E22:P22) -> 37391752 | R22: =D22-E22-F22-G22-H22-I22-J22-K22-L22-M22-N22-O22-P22 -> 187800274 | S22: 3303873 | T22: 3334021 | U22: 3364444 | V22: 3395144 | W22: 3426125 | X22: 3457388 | Y22: 3488937 | Z22: 3520774 | AA22: 3552901 | AB22: 3585321 | AC22: 3618037 | AD22: 3651051 | AE22: =R22-S22-T22-U22-V22-W22-X22-Y22-Z22-AA22-AB22-AC22-AD22 -> 146102258
A23: 20 | B23: Mahmur Mochtar | D23: ='Piutang Bank Mandiri -24'!F60 -> 21230965 | E23: {=TRANSPOSE('Piutang Bank Mandiri -24'!E61:E64)} -> 5235641 | F23: 5283417 | G23: 5331628 | H23: 5380279 | Q23: =SUM(E23:P23) -> 21230965 | R23: LUNAS | W23: 0 | Y23: 0 | Z23: 0 | AA23: 0 | AE23: LUNAS
A24: TOTAL | D24: =SUM(D4:D23) -> 2837383385 | E24: =SUM(E4:E23) -> 63298751 | F24: =SUM(F4:F23) -> 63876355 | G24: =SUM(G4:G23) -> 64459226 | H24: =SUM(H4:H23) -> 65047416 | I24: =SUM(I4:I23) -> 60211601 | J24: =SUM(J4:J23) -> 58589267 | K24: =SUM(K4:K23) -> 56272638 | ... AE24: =SUM(AE4:AE23) -> 1425177122
D25: ='Piutang Bank Mandiri -24'!F257 -> 2837383385 | E25: 63298751 | F25: 63876355 | G25: 64459226 | H25: 65047416 | I25: 60211601 | J25: 58589267 | K25: 56272635 | L25: 56786126 | M25: 49633858 | N25: 146895014 | O25: 50543809 | P25: 51005021 | S25: 50520017 | T25: 50981013 | U25: 51446214 | V25: 51915660 | W25: 52389391 | X25: 48378859 | Y25: 48864300 | Z25: 49310186 | AA25: 49760140 | AB25: 50214202 | AC25: 70672407 | AD25: 51134792 | AE25: 1425177123
D26: =D24-D25 -> 0 | E26: =E24-E25 -> 0 | F26: =F24-F25 -> 0 | G26: =G24-G25 -> 0 | H26: =H24-H25 -> 0 | I26: =I24-I25 -> 0 | J26: =J24-J25 -> 0 | K26: =K24-K25 -> 3 | ... AE26: =AE24-AE25 -> -1
B29: BANK BSI
A30: No | B30: Nama | D30: Piutang 2023 | E30: Angsuran | R30: PEMBAYARAN TAHUN 2025
E31: Januari | F31: Februari | G31: Maret | H31: April | I31: Mei | J31: Juni | K31: Juli | L31: Agustus | M31: September | N31: Oktober | O31: November | P31: Desember | Q31: TOTAL PEMBAYARAN 2024 | R31: Sisa Hutang 2024 | S31: JANUARI | T31: FEBRUARI | U31: MARET | V31: APRIL | W31: MEI | X31: JUNI | Y31: JULI | Z31: AGUSTUS | AA31: SEPTEMBER | AB31: OKTOBER | AC31: NOVEMBER | AD31: DESEMBER | AE31: Piutang
G32: Angsuran | I32: Angsuran
A33: 1 | B33: Achmad Tawakkal Rampa | C33: PUSAT | D33: 441301238 | E33: {=TRANSPOSE('Piutang Bank BSI-24'!E9:E20)} -> 2842239 | F33: 2868293 | G33: 2894586 | H33: 2921119 | I33: 2947896 | J33: 2974919 | K33: 3002189 | L33: 3029709 | M33: 3057481 | N33: 3085508 | O33: 3113792 | P33: 3142335 | Q33: =SUM(_xlfn.ANCHORARRAY(E33)) -> 35880066 | R33: =D33-E33-F33-G33-H33-I33-J33-K33-L33-M33-N33-O33-P33 -> 405421172 | S33: 3171140 | T33: 3200209 | U33: 3229544 | V33: 3259148 | W33: 3289024 | X33: 3319173 | Y33: 3349599 | Z33: 3380303 | AA33: 3411289 | AB33: 3442560 | AC33: 3474116 | AD33: 3505962 | AE33: =R33-S33-T33-U33-V33-W33-X33-Y33-Z33-AA33-AB33-AC33-AD33 -> 365389105
A34: 2 | B34: Agung Prihanto, Ir | D34: 80174732 | E34: {=TRANSPOSE('Piutang Bank BSI-24'!E23:E31)} -> 8586633 | F34: 8665343 | G34: 8744776 | H34: 8824936 | I34: 8905831 | J34: 8987468 | K34: 9069853 | L34: 9152994 | M34: 9236898 | Q34: =SUM(_xlfn.ANCHORARRAY(E34)) -> 80174732 | R34: LUNAS | AE34: LUNAS
A35: 3 | B35: Andi Lamappasessu | C35: PUSAT | D35: 259099951 | E35: {=TRANSPOSE('Piutang Bank BSI-24'!E37:E48)} -> 5234765 | F35: 5282751 | G35: 5331176 | H35: 5380045 | I35: 5429362 | J35: 5479131 | K35: 5529356 | L35: 5580042 | M35: 5631193 | N35: 5682812 | O35: 5734904 | P35: 5787474 | Q35: =SUM(_xlfn.ANCHORARRAY(E35)) -> 66083011 | R35: =D35-E35-F35-G35-H35-I35-J35-K35-L35-M35-N35-O35-P35 -> 193016940 | S35: 5840526 | T35: 5894064 | U35: 5948093 | V35: 6002617 | W35: 6057641 | X35: 6113170 | Y35: 6169207 | Z35: 6225758 | AA35: 6282828 | AB35: 6340420 | AC35: 6398541 | AD35: 6457194 | AE35: =R35-S35-T35-U35-V35-W35-X35-Y35-Z35-AA35-AB35-AC35-AD35 -> 119286881
A36: 4 | B36: Arief Budi Permana, Ir | D36: 168135207 | E36: {=TRANSPOSE('Piutang Bank BSI-24'!E51:E59)} -> 16146806 | F36: 16291455 | G36: 16437399 | H36: 16584651 | I36: 16733222 | J36: 16883124 | K36: 17034368 | L36: 17186967 | M36: 17340934 | Q36: =SUM(_xlfn.ANCHORARRAY(E36)) -> 150638926 | R36: =D36-E36-F36-G36-H36-I36-J36-K36-L36-M36-N36-O36-P36 -> 17496281 | AC36: 0 | AE36: =R36-S36-T36-U36-V36-W36-X36-Y36-Z36-AA36-AB36-AC36-AD36 -> 17496281
A37: 5 | B37: Dandi Rukmana | C37: ACADEMY | D37: 322608414 | E37: {=TRANSPOSE('Piutang Bank BSI-24'!E66:E77)} -> 2512754 | F37: 2537881 | G37: 2563260 | H37: 2588893 | I37: 2614782 | J37: 2640929 | K37: 2667339 | L37: 2694012 | M37: 2720952 | N37: 2748162 | O37: 2775643 | P37: 2803400 | Q37: =SUM(_xlfn.ANCHORARRAY(E37)) -> 31868007 | R37: =D37-E37-F37-G37-H37-I37-J37-K37-L37-M37-N37-O37-P37 -> 290740407 | S37: 2831434 | T37: 2859748 | U37: 2888346 | V37: 2917229 | W37: 2946401 | X37: =276297249-425000000+2015987 -> -146686764 | Y37: 2033627 | Z37: =250000000+168898964+2051421 -> 420950385 | AA37: - | AE37: LUNAS
A38: 6 | B38: Dede Ma'mun Sumantri | C38: PUSAT | D38: 167114617 | E38: ='Piutang Bank BSI-24'!E80 -> 4700818 | F38: ='Piutang Bank BSI-24'!E81 -> 4742929 | G38: ='Piutang Bank BSI-24'!E82 -> 4785418 | H38: ='Piutang Bank BSI-24'!E83 -> 4828287 | I38: ='Piutang Bank BSI-24'!E84-'Piutang Bank BSI-24'!D85 -> -91942839 | J38: ='Piutang Bank BSI-24'!E86 -> 7008660 | K38: ='Piutang Bank BSI-24'!E87 -> 7071445 | L38: ='Piutang Bank BSI-24'!E88 -> 7134794 | M38: ='Piutang Bank BSI-24'!E89 -> 7198710 | N38: ='Piutang Bank BSI-24'!E90 -> 7263198 | O38: ='Piutang Bank BSI-24'!E91 -> 7328264 | P38: ='Piutang Bank BSI-24'!E92 -> 7393913 | Q38: =SUM(_xlfn.ANCHORARRAY(E38)) -> 4700818 | R38: =D38-E38-F38-G38-H38-I38-J38-K38-L38-M38-N38-O38-P38 -> 189601020 | S38: 7460150 | T38: 7526981 | U38: 7594410 | V38: 7662443 | W38: 7731086 | X38: 7800344 | Y38: 7870222 | Z38: 7940726 | AA38: 8011862 | AB38: 8083635 | AC38: 8156050 | AD38: 8229115 | AE38: =R38-S38-T38-U38-V38-W38-X38-Y38-Z38-AA38-AB38-AC38-AD38 -> 95533996
A39: 7 | B39: Elis Rosida | C39: PUSAT | D39: 101419449 | E39: {=TRANSPOSE('Piutang Bank BSI-24'!E96:E107)} -> 3981129 | F39: 4017623 | G39: 4054451 | H39: 4091617 | I39: 4129123 | J39: 4166974 | K39: 4205171 | L39: 4243718 | M39: 4282619 | N39: 4321877 | O39: 4361494 | P39: 4401474 | Q39: =SUM(_xlfn.ANCHORARRAY(E39)) -> 50257270 | R39: =D39-E39-F39-G39-H39-I39-J39-K39-L39-M39-N39-O39-P39 -> 51162179 | S39: 4441821 | T39: 4482538 | U39: 4523628 | V39: 4565094 | W39: 4606941 | X39: 4649171 | Y39: 4691789 | Z39: 4734797 | AA39: 14466400 | AB39: 0 | AE39: =R39-S39-T39-U39-V39-W39-X39-Y39-Z39-AA39-AB39 -> 0
A40: 8 | B40: Endah Mustika Ningtias | C40: PUSAT | D40: 145619024 | E40: {=TRANSPOSE('Piutang Bank BSI-24'!E110:E121)} -> 1178507 | F40: 1189310 | G40: 1200212 | H40: 1211214 | I40: 1222317 | J40: 1233521 | K40: 1244829 | L40: 1256240 | M40: 1267755 | N40: 1279376 | O40: 1291104 | P40: 1302939 | Q40: =SUM(_xlfn.ANCHORARRAY(E40)) -> 14877324 | R40: =D40-E40-F40-G40-H40-I40-J40-K40-L40-M40-N40-O40-P40 -> 130741700 | S40: 1314883 | T40: 1326936 | U40: 1339099 | V40: 1351374 | W40: 1363762 | X40: 1376263 | Y40: 1388879 | Z40: 1401610 | AA40: =-175000000+119878894+2230183 -> -52890923 | AB40: 2249697 | AC40: 2269381 | AD40: 2289239 | AE40: =R40-S40-T40-U40-V40-W40-X40-Y40-Z40-AA40-AB40-AC40-AD40 -> 165961500
A41: 9 | B41: Eva Sintauli Saragih | C41: PUSAT | D41: 465541913 | E41: {=TRANSPOSE('Piutang Bank BSI-24'!E124:E135)} -> 3045463 | F41: 3073380 | G41: 3101552 | H41: 3129983 | I41: 3158675 | J41: 3187629 | K41: 3216849 | L41: 3246337 | M41: 3276095 | N41: 3306126 | O41: 3336432 | P41: 3367016 | Q41: =SUM(_xlfn.ANCHORARRAY(E41)) -> 38445537 | R41: =D41-E41-F41-G41-H41-I41-J41-K41-L41-M41-N41-O41-P41 -> 427096376 | S41: 3397880 | T41: 3429028 | U41: 3460460 | V41: 3492181 | W41: 3524193 | X41: 3556498 | Y41: 3589099 | Z41: 3621999 | AA41: 3655201 | AB41: 3688707 | AC41: 3722520 | AD41: 3756643 | AE41: =R41-S41-T41-U41-V41-W41-X41-Y41-Z41-AA41-AB41-AC41-AD41 -> 384201967
A42: 10 | B42: Haerudin | C42: PUSAT | D42: 0 | E42: 0 | F42: 0 | G42: =-'Piutang Bank BSI-24'!D137 -> -110000000 | H42: ='Piutang Bank BSI-24'!E138 -> 2781918 | I42: ='Piutang Bank BSI-24'!E139 -> 2806839 | J42: ='Piutang Bank BSI-24'!E140 -> 2831984 | K42: ='Piutang Bank BSI-24'!E141 -> 2857354 | L42: ='Piutang Bank BSI-24'!E142 -> 2882951 | M42: ='Piutang Bank BSI-24'!E143 -> 2908777 | N42: ='Piutang Bank BSI-24'!E144 -> 2934835 | O42: ='Piutang Bank BSI-24'!E145 -> 2961126 | P42: ='Piutang Bank BSI-24'!E146 -> 2987653 | Q42: =SUM(H42:P42) -> 25953437 | R42: =D42-E42-F42-G42-H42-I42-J42-K42-L42-M42-N42-O42-P42 -> 84046563 | S42: 3014418 | T42: 3041422 | U42: 3068668 | V42: 3096158 | W42: 3123894 | X42: 3151879 | Y42: 3180115 | Z42: 3208603 | AA42: 3237347 | AB42: 3266348 | AC42: 3295609 | AD42: 3325133 | AE42: =R42-S42-T42-U42-V42-W42-X42-Y42-Z42-AA42-AB42-AC42-AD42 -> 46036969
...

Sheet Sheet1
A3: Rincian pengembalian atas kelebihan potongan pinjaman BSI an Mahmur Mochtar
A5: Sisa Hutang Tahun 2024 | B5: ='REKAP PIUTANG BANK'!$R$47 -> 51162179
A6: Angsuran pembayaran selama 2025 | B6: =-SUM('REKAP PIUTANG BANK'!S47+'REKAP PIUTANG BANK'!T47+'REKAP PIUTANG BANK'!U47+4565094+4606941) -> -22620022
A7: Penambahan pinjaman di bulan Mei 2025 | B7: 200000000
A8: Pelunasan Pokok dengan pinjaman baru | B8: -33149096
A9: Sisa Pinjaman per mei 2025 | B9: =SUM(B5:B8) -> 1.9539306e+08
A10: Pembayaran Pinjaman dengan potongan baru | B10: =-(2548780+2571082+2593579+2616273+2639165+2662258+2685553) -> -18316690
A11: Sisa Pinjaman per Desember 2025 | B11: 177076370
A12: Pelunasan dengan asuransi karena meninggal | B12: -181683311
A13: Selisih lebih bayar potongan di bulan Mei 2025 | B13: =B12+B11 -> -4606941
A15: Note: Pak Mahmur tetap dipotong saat bulan mei pengajuan pinjaman baru
A18: Jakarta, 5 Februari 2026
A19: Mengetahui, | B19: Pembuat Daftar,
A23: Dea Adawiyah | B23: Shaidatun Rohmah

Sheet Sheet3
A2: BSI FARIED
B3: Pokok Ditagih | C3: Pokok Seharusnya | D3: Selisih
A4: April | B4: 1636437 | C4: 1660225 | D4: =B4-C4 -> -23788
A5: Mei | B5: 1651097 | C5: 1674752 | D5: =B5-C5 -> -23655
B7: Jasa Ditagih | C7: Jasa Seharusnya | D7: Selisih
A8: April | B8: 3135417 | C8: 3062500 | D8: =B8-C8 -> 72917 | F8: =D8+D4 -> 49129
A9: Mei | B9: 3120757 | C9: 3047873 | D9: =B9-C9 -> 72884

Sheet Piutang Bank Mandiri -24
A1: PIUTANG BANK MANDIRI
D3: ANGSURAN | F3: SALDO AWAL | G3: SALDO AKHIR
D4: D | E4: K
B5: Erry Sanjaya Djayus
A6: 45292 | B6: Memo | C6: Saldo Awal | F6: 10567703
A7: 45316 | B7: Kasa | C7: Angsuran Pinjaman Bank Mandiri Erry Sanjaya Djayus | E7: 2075319 | G7: =F6-E7 -> 8492384
A8: 45345 | B8: Kasa | C8: Angsuran Pinjaman Bank Mandiri Erry Sanjaya Djayus | E8: 2094257 | G8: =G7-E8 -> 6398127
A9: 45376 | B9: Kasa | C9: Angsuran Pinjaman Bank Mandiri Erry Sanjaya Djayus | E9: 2113367 | G9: =G8-E9 -> 4284760
A10: 45407 | B10: Kasa | C10: Angsuran Pinjaman Bank Mandiri Erry Sanjaya Djayus | E10: 2132651 | G10: =G9-E10 -> 2152109
A11: 45434 | B11: Kasa | C11: Angsuran Pinjaman Bank Mandiri Erry Sanjaya Djayus | E11: 2152112 | G11: =G10-E11 -> -3
A12: 45504 | B12: Memo | C12: Selisih Pembulatan Pinjaman Bank Mandiri Erry Sanjaya Djayus | D12: 3 | G12: =G11+D12 -> 0
B13: Eva Sintauli Saragih, SE
A14: 45292 | B14: Memo | C14: Saldo Awal | F14: 287816220
A15: 45316 | B15: Kasa | C15: Angsuran Pinjaman Bank Mandiri Eva Sintauli Saragih, SE | E15: 4247034 | G15: =F14-E15 -> 283569186
A16: 45345 | B16: Kasa | C16: Angsuran Pinjaman Bank Mandiri Eva Sintauli Saragih, SE | E16: 4285788 | G16: =G15-E16 -> 279283398
A17: 45376 | B17: Kasa | C17: Angsuran Pinjaman Bank Mandiri Eva Sintauli Saragih, SE | E17: 4324896 | G17: =G16-E17 -> 274958502
A18: 45407 | B18: Kasa | C18: Angsuran Pinjaman Bank Mandiri Eva Sintauli Saragih, SE | E18: 4364360 | G18: =G17-E18 -> 270594142
A19: 45434 | B19: Kasa | C19: Angsuran Pinjaman Bank Mandiri Eva Sintauli Saragih, SE | E19: 4404185 | G19: =G18-E19 -> 266189957
A20: 45468 | B20: Kasa | C20: Angsuran Pinjaman Bank Mandiri Eva Sintauli Saragih, SE | E20: 4444373 | G20: =G19-E20 -> 261745584
A21: 45498 | B21: Kasa | C21: Angsuran Pinjaman Bank MandiriEva Sintauli Saragih, SE | E21: 4484928 | G21: =G20-E21 -> 257260656
A22: 45527 | B22: Kasa | C22: Angsuran Pinjaman Bank Mandiri Eva Sintauli Saragih, SE | E22: 4525853 | G22: =G21-E22 -> 252734803
A23: 45560 | B23: Kasa | C23: Angsuran Pinjaman Bank Mandiri Eva Sintauli Saragih, SE | E23: 4567152 | G23: =G22-E23 -> 248167651
A24: 45590 | B24: Kasa | C24: Angsuran Pinjaman Bank Mandiri Eva Sintauli Saragih, SE | E24: 4608827 | G24: =G23-E24 -> 243558824
A25: 45621 | B25: Kasa | C25: Angsuran Pinjaman Bank Mandiri Eva Sintauli Saragih, SE | E25: 4650883
A26: 45649 | B26: Kasa | C26: Angsuran Pinjaman Bank Mandiri Eva Sintauli Saragih, SE | E26: 4693322
B28: Indra Permana
A29: 45292 | B29: Memo | C29: Saldo Awal | F29: 225192026
A30: 45316 | B30: Memo | C30: Angsuran Pinjaman Bank Mandiri Indra Permana | E30: 2962673 | G30: =F29-E30 -> 222229353
A31: 45345 | B31: Kasa | C31: Angsuran Pinjaman Bank Mandiri Indra Permana | E31: 2989708 | G31: =G30-E31 -> 219239645
A32: 45376 | B32: Kasa | C32: Angsuran Pinjaman Bank Mandiri Indra Permana | E32: 3016989 | G32: =G31-E32 -> 216222656
A33: 45407 | B33: Kasa | C33: Angsuran Pinjaman Bank Mandiri Indra Permana | E33: 3044519 | G33: =G32-E33 -> 213178137
A34: 45434 | B34: Kasa | C34: Angsuran Pinjaman Bank Mandiri Indra Permana | E34: 3072300 | G34: =G33-E34 -> 210105837
A35: 45468 | B35: Kasa | C35: Angsuran Pinjaman Bank Mandiri Indra Permana | E35: 3100335 | G35: =G34-E35 -> 207005502
A36: 45498 | B36: Kasa | C36: Angsuran Pinjaman Bank Mandiri Indra Permana | E36: 3128625 | G36: =G35-E36 -> 203876877
A37: 45527 | B37: Kasa | C37: Angsuran Pinjaman Bank Mandiri Indra Permana | E37: 3157174 | G37: =G36-E37 -> 200719703
A38: 45560 | B38: Kasa | C38: Angsuran Pinjaman Bank Mandiri Indra Permana | E38: 3185983 | G38: =G37-E38 -> 197533720
A39: 45590 | B39: Kasa | C39: Angsuran Pinjaman Bank Mandiri Indra Permana | E39: 3215055 | G39: =G38-E39 -> 194318665
A40: 45621 | B40: Kasa | C40: Angsuran Pinjaman Bank Mandiri Indra Permana | E40: 3244393
A41: 45649 | B41: Kasa | C41: Angsuran Pinjaman Bank Mandiri Indra Permana | E41: 3273998
B44: Irwanto, B.Sc.
...

Sheet Piutang Bank BSI-24
A3: 1104.008
D5: ANGSURAN | F5: SALDO AWAL | G5: SALDO AKHIR
D6: D | E6: K
B7: Achmad Tawakkal
A8: 45292 | B8: Memo | C8: Saldo Awal | F8: 441301238
A9: 45316 | B9: Kasa | C9: Angsuran Pinjaman Bank BSI Achmad Tawakkal | E9: 2842239 | G9: =F8-E9 -> 438458999
A10: 45345 | B10: Kasa | C10: Angsuran Pinjaman Bank BSI Achmad Tawakkal | E10: 2868293 | G10: =G9-E10 -> 435590706
A11: 45376 | B11: Kasa | C11: Angsuran Pinjaman Bank BSI Achmad Tawakkal | E11: 2894586 | G11: =G10-E11 -> 432696120
A12: 45407 | B12: Kasa | C12: Angsuran Pinjaman Bank BSI Achmad Tawakkal | E12: 2921119 | G12: =G11-E12 -> 429775001
A13: 45434 | B13: Kasa | C13: Angsuran Pinjaman Bank BSI Achmad Tawakkal | E13: 2947896 | G13: =G12-E13 -> 426827105
A14: 45468 | B14: Kasa | C14: Angsuran Pinjaman Bank BSI Achmad Tawakkal | E14: 2974919 | G14: =G13-E14 -> 423852186
A15: 45498 | B15: Kasa | C15: Angsuran Pinjaman Bank BSI Achmad Tawakkal | E15: 3002189 | G15: =G14-E15 -> 420849997
A16: 45527 | B16: Kasa | C16: Angsuran Pinjaman Bank BSI Achmad Tawakkal | E16: 3029709 | G16: =G15-E16 -> 417820288
A17: 45560 | B17: Kasa | C17: Angsuran Pinjaman Bank BSI Achmad Tawakkal | E17: 3057481 | G17: =G16-E17 -> 414762807
A18: 45590 | B18: Kasa | C18: Angsuran Pinjaman Bank BSI Achmad Tawakkal | E18: 3085508 | G18: =G17-E18 -> 411677299
A19: 45621 | B19: Kasa | C19: Angsuran Pinjaman Bank BSI Achmad Tawakkal | E19: 3113792 | G19: =G18-E19 -> 408563507
A20: 45649 | B20: Kasa | C20: Angsuran Pinjaman Bank BSI Achmad Tawakkal | E20: 3142335 | G20: =G19-E20 -> 405421172
B21: Agung Prihanto, Ir
A22: 45292 | B22: Memo | C22: Saldo Awal | F22: 80174732
A23: 45316 | B23: Kasa | C23: Angsuran Pinjaman Bank BSI Agung Prihanto, Ir | E23: 8586633 | G23: =F22-E23 -> 71588099
A24: 45345 | B24: Kasa | C24: Angsuran Pinjaman Bank BSI Agung Prihanto, Ir | E24: 8665343 | G24: =G23-E24 -> 62922756
A25: 45376 | B25: Kasa | C25: Angsuran Pinjaman Bank BSI Agung Prihanto, Ir | E25: 8744776 | G25: =G24-E25 -> 54177980
A26: 45407 | B26: Kasa | C26: Angsuran Pinjaman Bank BSI Agung Prihanto, Ir | E26: 8824936 | G26: =G25-E26 -> 45353044
A27: 45434 | B27: Kasa | C27: Angsuran Pinjaman Bank BSI Agung Prihanto, Ir | E27: 8905831 | G27: =G26-E27 -> 36447213
A28: 45468 | B28: Kasa | C28: Angsuran Pinjaman Bank BSI Agung Prihanto, Ir | E28: 8987468 | G28: =G27-E28 -> 27459745
A29: 45498 | B29: Kasa | C29: Angsuran Pinjaman Bank BSI Agung Prihanto, Ir | E29: 9069853 | G29: =G28-E29 -> 18389892
A30: 45527 | B30: Kasa | C30: Angsuran Pinjaman Bank BSI Agung Prihanto, Ir | E30: 9152994 | G30: =G29-E30 -> 9236898
A31: 45560 | B31: Kasa | C31: Angsuran Pinjaman Bank BSI Agung Prihanto, Ir | E31: 9236898 | G31: =G30-E31 -> 0
B35: Andi Lama Passesu
A36: 45292 | B36: Memo | C36: Saldo Awal | F36: 259099951
A37: 45316 | B37: Kasa | C37: Angsuran Pinjaman Bank BSI Andi Lama Passesu | E37: 5234765 | G37: =F36-E37 -> 253865186
A38: 45345 | B38: Kasa | C38: Angsuran Pinjaman Bank BSI Andi Lama Passesu | E38: 5282751 | G38: =G37-E38 -> 248582435
A39: 45376 | B39: Kasa | C39: Angsuran Pinjaman Bank BSI Andi Lama Passesu | E39: 5331176 | G39: =G38-E39 -> 243251259
A40: 45407 | B40: Kasa | C40: Angsuran Pinjaman Bank BSI Andi Lama Passesu | E40: 5380045 | G40: =G39-E40 -> 237871214
A41: 45434 | B41: Kasa | C41: Angsuran Pinjaman Bank BSI Andi Lama Passesu | E41: 5429362 | G41: =G40-E41 -> 232441852
A42: 45468 | B42: Kasa | C42: Angsuran Pinjaman Bank BSI Andi Lama Passesu | E42: 5479131 | G42: =G41-E42 -> 226962721
A43: 45498 | B43: Kasa | C43: Angsuran Pinjaman Bank BSI Andi Lama Passesu | E43: 5529356 | G43: =G42-E43 -> 221433365
A44: 45527 | B44: Kasa | C44: Angsuran Pinjaman Bank BSI Andi Lama Passesu | E44: 5580042 | G44: =G43-E44 -> 215853323
A45: 45560 | B45: Kasa | C45: Angsuran Pinjaman Bank BSI Andi Lama Passesu | E45: 5631193 | G45: =G44-E45 -> 210222130
A46: 45590 | B46: Kasa | C46: Angsuran Pinjaman Bank BSI Andi Lama Passesu | E46: 5682812 | G46: =G45-E46 -> 204539318
...

Sheet Piutang Bank Mandiri -25
A1: PIUTANG BANK MANDIRI
D3: ANGSURAN | F3: SALDO AWAL | G3: SALDO AKHIR
D4: D | E4: K
B5: Eva Sintauli Saragih, SE
A6: 45658 | B6: Memo | C6: Saldo Awal | F6: ='REKAP PIUTANG BANK'!$R$9 -> 234214619
A7: 45682 | B7: Kasa | C7: Angsuran Pinjaman Bank Mandiri Eva Sintauli Saragih, SE | E7: 4736148 | G7: =F6-E7 -> 229478471
A8: 45711 | B8: Kasa | C8: Angsuran Pinjaman Bank Mandiri Eva Sintauli Saragih, SE | E8: 4779366 | G8: =G7-E8 -> 224699105
A9: 45741 | B9: Kasa | C9: Angsuran Pinjaman Bank Mandiri Eva Sintauli Saragih, SE | E9: 4822977 | G9: =G8-E9 -> 219876128
A10: 45772 | B10: Kasa | C10: Angsuran Pinjaman Bank Mandiri Eva Sintauli Saragih, SE | E10: 4866987 | G10: =G9-E10 -> 215009141
B11: Kasa | C11: Angsuran Pinjaman Bank Mandiri Eva Sintauli Saragih, SE | G11: =G10-E11 -> 215009141
B12: Kasa | C12: Angsuran Pinjaman Bank Mandiri Eva Sintauli Saragih, SE | G12: =G11-E12 -> 215009141
B13: Kasa | C13: Angsuran Pinjaman Bank MandiriEva Sintauli Saragih, SE | G13: =G12-E13 -> 215009141
B14: Kasa | C14: Angsuran Pinjaman Bank Mandiri Eva Sintauli Saragih, SE | G14: =G13-E14 -> 215009141
B15: Kasa | C15: Angsuran Pinjaman Bank Mandiri Eva Sintauli Saragih, SE | G15: =G14-E15 -> 215009141
B16: Kasa | C16: Angsuran Pinjaman Bank Mandiri Eva Sintauli Saragih, SE | G16: =G15-E16 -> 215009141
B17: Kasa | C17: Angsuran Pinjaman Bank Mandiri Eva Sintauli Saragih, SE | G17: =G16-E17 -> 215009141
B18: Kasa | C18: Angsuran Pinjaman Bank Mandiri Eva Sintauli Saragih, SE | G18: =G17-E18 -> 215009141
B20: Indra Permana
A21: 45658 | B21: Memo | C21: Saldo Awal | F21: ='REKAP PIUTANG BANK'!$R$22 -> 187800274
B22: Memo | C22: Angsuran Pinjaman Bank Mandiri Indra Permana | E22: 3303873 | G22: =F21-E22 -> 184496401
B23: Kasa | C23: Angsuran Pinjaman Bank Mandiri Indra Permana | E23: 3334021 | G23: =G22-E23 -> 181162380
B24: Kasa | C24: Angsuran Pinjaman Bank Mandiri Indra Permana | E24: 3364444 | G24: =G23-E24 -> 177797936
B25: Kasa | C25: Angsuran Pinjaman Bank Mandiri Indra Permana | E25: 3395144 | G25: =G24-E25 -> 174402792
B26: Kasa | C26: Angsuran Pinjaman Bank Mandiri Indra Permana | G26: =G25-E26 -> 174402792
B27: Kasa | C27: Angsuran Pinjaman Bank Mandiri Indra Permana | G27: =G26-E27 -> 174402792
B28: Kasa | C28: Angsuran Pinjaman Bank Mandiri Indra Permana | G28: =G27-E28 -> 174402792
B29: Kasa | C29: Angsuran Pinjaman Bank Mandiri Indra Permana | G29: =G28-E29 -> 174402792
B30: Kasa | C30: Angsuran Pinjaman Bank Mandiri Indra Permana | G30: =G29-E30 -> 174402792
B31: Kasa | C31: Angsuran Pinjaman Bank Mandiri Indra Permana | G31: =G30-E31 -> 174402792
B32: Kasa | C32: Angsuran Pinjaman Bank Mandiri Indra Permana | G32: =G31-E32 -> 174402792
B33: Kasa | C33: Angsuran Pinjaman Bank Mandiri Indra Permana | G33: =G32-E33 -> 174402792
B36: Irwanto, B.Sc.
A37: 45658 | B37: Memo | C37: Saldo Awal | F37: ='REKAP PIUTANG BANK'!$R$6 -> 114739229
B38: Memo | C38: Angsuran Pinjaman Bank Mandiri Irwanto, B.Sc. | E38: 2389683 | G38: =F37-E38 -> 112349546
B39: Kasa | C39: Angsuran Pinjaman Bank Mandiri Irwanto, B.Sc. | E39: 2411489 | G39: =G38-E39 -> 109938057
B40: Kasa | C40: Angsuran Pinjaman Bank Mandiri Irwanto, B.Sc. | E40: 2433494 | G40: =G39-E40 -> 107504563
B41: Kasa | C41: Angsuran Pinjaman Bank Mandiri Irwanto, B.Sc. | E41: 2455699 | G41: =G40-E41 -> 105048864
B42: Kasa | C42: Angsuran Pinjaman Bank Mandiri Irwanto, B.Sc. | G42: =G41-E42 -> 105048864
B43: Kasa | C43: Angsuran Pinjaman Bank Mandiri Irwanto, B.Sc. | G43: =G42-E43 -> 105048864
B44: Kasa | C44: Angsuran Pinjaman Bank Mandiri Irwanto, B.Sc. | G44: =G43-E44 -> 105048864
...

Sheet Piutang Bank BSI - 25
A3: 1104.008
D5: ANGSURAN | F5: SALDO AWAL | G5: SALDO AKHIR
D6: D | E6: K
B7: Achmad Tawakkal
A8: 45658 | B8: Memo | C8: Saldo Awal | F8: 405421172
A9: 45682 | B9: Kasa | C9: Angsuran Pinjaman Bank BSI Achmad Tawakkal | E9: 3171140 | G9: =F8-E9 -> 402250032
A10: 45711 | B10: Kasa | C10: Angsuran Pinjaman Bank BSI Achmad Tawakkal | E10: 3200209 | G10: =G9-E10 -> 399049823
A11: 45741 | B11: Kasa | C11: Angsuran Pinjaman Bank BSI Achmad Tawakkal | E11: 3229544 | G11: =G10-E11 -> 395820279
A12: 45772 | B12: Kasa | C12: Angsuran Pinjaman Bank BSI Achmad Tawakkal | E12: 3259148 | G12: =G11-E12 -> 392561131
B13: Kasa | C13: Angsuran Pinjaman Bank BSI Achmad Tawakkal | G13: =G12-E13 -> 392561131
B14: Kasa | C14: Angsuran Pinjaman Bank BSI Achmad Tawakkal | G14: =G13-E14 -> 392561131
B15: Kasa | C15: Angsuran Pinjaman Bank BSI Achmad Tawakkal | G15: =G14-E15 -> 392561131
B16: Kasa | C16: Angsuran Pinjaman Bank BSI Achmad Tawakkal | G16: =G15-E16 -> 392561131
B17: Kasa | C17: Angsuran Pinjaman Bank BSI Achmad Tawakkal | G17: =G16-E17 -> 392561131
B18: Kasa | C18: Angsuran Pinjaman Bank BSI Achmad Tawakkal | G18: =G17-E18 -> 392561131
B19: Kasa | C19: Angsuran Pinjaman Bank BSI Achmad Tawakkal | G19: =G18-E19 -> 392561131
B20: Kasa | C20: Angsuran Pinjaman Bank BSI Achmad Tawakkal
B21: Agung Prihanto, Ir
A22: 45658 | B22: Memo | C22: Saldo Awal | F22: 0
B23: Kasa | C23: Angsuran Pinjaman Bank BSI Agung Prihanto, Ir | E23: 0 | G23: 0
B24: Kasa | C24: Angsuran Pinjaman Bank BSI Agung Prihanto, Ir | E24: 0 | G24: 0
B25: Kasa | C25: Angsuran Pinjaman Bank BSI Agung Prihanto, Ir | E25: 0 | G25: 0
B26: Kasa | C26: Angsuran Pinjaman Bank BSI Agung Prihanto, Ir | E26: 0 | G26: 0
B27: Kasa | C27: Angsuran Pinjaman Bank BSI Agung Prihanto, Ir | E27: 0 | G27: 0
B28: Kasa | C28: Angsuran Pinjaman Bank BSI Agung Prihanto, Ir | E28: 0 | G28: 0
B29: Kasa | C29: Angsuran Pinjaman Bank BSI Agung Prihanto, Ir | E29: 0 | G29: 0
B30: Kasa | C30: Angsuran Pinjaman Bank BSI Agung Prihanto, Ir | E30: 0 | G30: 0
B31: Kasa | C31: Angsuran Pinjaman Bank BSI Agung Prihanto, Ir | E31: 0 | G31: 0
B35: Andi Lama Passesu
A36: 45658 | B36: Memo | C36: Saldo Awal | F36: 193016940
A37: 45682 | B37: Kasa | C37: Angsuran Pinjaman Bank BSI Andi Lama Passesu | E37: 5840526 | G37: =F36-E37 -> 187176414
A38: 45711 | B38: Kasa | C38: Angsuran Pinjaman Bank BSI Andi Lama Passesu | E38: 5894064 | G38: =G37-E38 -> 181282350
A39: 45741 | B39: Kasa | C39: Angsuran Pinjaman Bank BSI Andi Lama Passesu | E39: 5948093 | G39: =G38-E39 -> 175334257
A40: 45772 | B40: Kasa | C40: Angsuran Pinjaman Bank BSI Andi Lama Passesu | E40: 6002617 | G40: =G39-E40 -> 169331640
B41: Kasa | C41: Angsuran Pinjaman Bank BSI Andi Lama Passesu | G41: =G40-E41 -> 169331640
B42: Kasa | C42: Angsuran Pinjaman Bank BSI Andi Lama Passesu | G42: =G41-E42 -> 169331640
B43: Kasa | C43: Angsuran Pinjaman Bank BSI Andi Lama Passesu | G43: =G42-E43 -> 169331640
B44: Kasa | C44: Angsuran Pinjaman Bank BSI Andi Lama Passesu | G44: =G43-E44 -> 169331640
B45: Kasa | C45: Angsuran Pinjaman Bank BSI Andi Lama Passesu | G45: =G44-E45 -> 169331640
B46: Kasa | C46: Angsuran Pinjaman Bank BSI Andi Lama Passesu | G46: =G45-E46 -> 169331640
...
